Workbook

Sheet whole_data
AI1: rs-sys | AJ1: rs-sys | AK1: rs-sys | AL1: rs-sys | AM1: rs-sys | AN1: rs-pure | AO1: rs-pure | AP1: rs-pure | AQ1: rs-pure | AR1: clang | AS1: clang | AT1: clang | AU1: gcc | AV1: gcc | AW1: go | AX1: linux | AY1: linux | AZ1: darwin
B2: left | E2: right | H2: cosine | I2: dice | J2: euclidean | K2: jaccard | L2: lcs | M2: levenshtein | N2: simpson | O2: weighted-jaccard | P2: Clang (Linux) | Q2: Gcc (Linux) | R2: Go (Linux) | S2: TinyGo (Linux) | T2: Clang (Darwin) | U2: Gcc (Darwin) | V2: Go (Darwin) | W2: TinyGo (Darwin) | X2: Clang (Windows) | Y2: Gcc (Windows) | Z2: MSVC (Windows) | AA2: Go (Windows) | AB2: both_windows_clang | AC2: both C | AD2: both Go | AE2: both Rust | AF2: same_os | AG2: same_arch | AH2: same_lang | AI2: rs-pure | AJ2: clang | AK2: gcc | AL2: go | AM2: tgo | AN2: clang | AO2: gcc | AP2: go | AQ2: tgo | AR2: gcc | AS2: go | AT2: tgo | AU2: go | AV2: tgo | AW2: tgo | AX2: darwin | AY2: windows | AZ2: windows | BA2: Rust | BB2: Windows
A3: 0 | B3: amd64 | C3: darwin | D3: clang | E3: amd64 | F3: darwin | G3: gcc | H3: 0.87163701 | I3: 0.82714709 | J3: 0.69909621 | K3: 0.75657224 | L3: 0.56891009 | M3: 0.46040662 | N3: 0.94029851 | O3: 0.60038919 | P3: =IF(OR(AND($C3="linux",$D3="clang"),AND($F3="linux",$G3="clang")),1,0) -> 0 | Q3: =IF(OR(AND($C3="linux",$D3="gcc"),AND($F3="linux",$G3="gcc")),1,0) -> 0 | R3: =IF(OR(AND($C3="linux",$D3="go"),AND($F3="linux",$G3="go")),1,0) -> 0 | S3: =IF(OR(AND($C3="linux",$D3="tgo"),AND($F3="linux",$G3="tgo")),1,0) -> 0 | T3: =IF(OR(AND($C3="darwin",$D3="clang"),AND($F3="darwin",$G3="clang")),1,0) -> 1 | U3: =IF(OR(AND($C3="darwin",$D3="gcc"),AND($F3="darwin",$G3="gcc")),1,0) -> 1 | V3: =IF(OR(AND($C3="darwin",$D3="go"),AND($F3="darwin",$G3="go")),1,0) -> 0 | W3: =IF(OR(AND($C3="darwin",$D3="tgo"),AND($F3="darwin",$G3="tgo")),1,0) -> 0 | X3: =IF(OR(AND($C3="windows",$D3="clang"),AND($F3="windows",$G3="clang")),1,0) -> 0 | Y3: =IF(OR(AND($C3="windows",$D3="gcc"),AND($F3="windows",$G3="gcc")),1,0) -> 0 | Z3: =IF(OR(AND($C3="windows",$D3="msvc"),AND($F3="windows",$G3="msvc")),1,0) -> 0 | AA3: =IF(OR(AND($C3="windows",$D3="go"),AND($F3="windows",$G3="go")),1,0) -> 0 | AB3: =IF(AND(AND(C3="windows",D3="clang"),AND(F3="windows",G3="clang")),1,0) -> 0 | AC3: =IF(AND(OR(D3="clang",D3="gcc",D3="msvc"),OR(G3="gcc",G3="clang",G3="msvc")),1,0) -> 1 | AD3: =IF(AND(OR(D3="go",D3="tgo"),OR(G3="go",G3="tgo")),1,0) -> 0 | AE3: =IF(AND(OR(D3="rs-pure",D3="rs-sys"),OR(G3="rs-pure",G3="rs-sys")),1,0) -> 0 | AF3: =IF(C3=F3,1,0) -> 1 | AG3: =IF(B3=E3,1,0) -> 1 | AH3: =IF(SUM(AC3:AE3)=1,1,0) -> 1 | AI3: =IF(OR(AND($D3=AI$1,$G3=AI$2),AND($D3=AI$2,$G3=AI$1)),1,0) -> 0 | AJ3: =IF(OR(AND($D3=AJ$1,$G3=AJ$2),AND($D3=AJ$2,$G3=AJ$1)),1,0) -> 0 | AK3: =IF(OR(AND($D3=AK$1,$G3=AK$2),AND($D3=AK$2,$G3=AK$1)),1,0) -> 0 | AL3: =IF(OR(AND($D3=AL$1,$G3=AL$2),AND($D3=AL$2,$G3=AL$1)),1,0) -> 0 | AM3: =IF(OR(AND($D3=AM$1,$G3=AM$2),AND($D3=AM$2,$G3=AM$1)),1,0) -> 0 | AN3: =IF(OR(AND($D3=AN$1,$G3=AN$2),AND($D3=AN$2,$G3=AN$1)),1,0) -> 0 | AO3: =IF(OR(AND($D3=AO$1,$G3=AO$2),AND($D3=AO$2,$G3=AO$1)),1,0) -> 0 | AP3: =IF(OR(AND($D3=AP$1,$G3=AP$2),AND($D3=AP$2,$G3=AP$1)),1,0) -> 0 | ... AW3: =IF(OR(AND($D3=AW$1,$G3=AW$2),AND($D3=AW$2,$G3=AW$1)),1,0) -> 0 | AX3: =IF(OR(AND($C3=AX$1,$F3=AX$2),AND($C3=AX$2,$F3=AX$1)),1,0) -> 0 | AY3: =IF(OR(AND($C3=AY$1,$F3=AY$2),AND($C3=AY$2,$F3=AY$1)),1,0) -> 0 | AZ3: =IF(OR(AND($C3=AZ$1,$F3=AZ$2),AND($C3=AZ$2,$F3=AZ$1)),1,0) -> 0 | BA3: =IF(SUM(AI3:AQ3)=1,1,0) -> 0 | BB3: =IF(OR(C3="windows",F3="windows"),1,0) -> 0
A4: 1 | B4: amd64 | C4: darwin | D4: clang | E4: amd64 | F4: darwin | G4: go | H4: 0.023006215 | I4: 0.022069064 | J4: 0.019007531 | K4: 0.020150652 | L4: 0.014169659 | M4: 0.011019912 | N4: 0.024618992 | O4: 0.015347093 | P4: =IF(OR(AND($C4="linux",$D4="clang"),AND($F4="linux",$G4="clang")),1,0) -> 0 | Q4: =IF(OR(AND($C4="linux",$D4="gcc"),AND($F4="linux",$G4="gcc")),1,0) -> 0 | R4: =IF(OR(AND($C4="linux",$D4="go"),AND($F4="linux",$G4="go")),1,0) -> 0 | S4: =IF(OR(AND($C4="linux",$D4="tgo"),AND($F4="linux",$G4="tgo")),1,0) -> 0 | T4: =IF(OR(AND($C4="darwin",$D4="clang"),AND($F4="darwin",$G4="clang")),1,0) -> 1 | U4: =IF(OR(AND($C4="darwin",$D4="gcc"),AND($F4="darwin",$G4="gcc")),1,0) -> 0 | V4: =IF(OR(AND($C4="darwin",$D4="go"),AND($F4="darwin",$G4="go")),1,0) -> 1 | W4: =IF(OR(AND($C4="darwin",$D4="tgo"),AND($F4="darwin",$G4="tgo")),1,0) -> 0 | X4: =IF(OR(AND($C4="windows",$D4="clang"),AND($F4="windows",$G4="clang")),1,0) -> 0 | Y4: =IF(OR(AND($C4="windows",$D4="gcc"),AND($F4="windows",$G4="gcc")),1,0) -> 0 | Z4: =IF(OR(AND($C4="windows",$D4="msvc"),AND($F4="windows",$G4="msvc")),1,0) -> 0 | AA4: =IF(OR(AND($C4="windows",$D4="go"),AND($F4="windows",$G4="go")),1,0) -> 0 | AB4: =IF(AND(AND(C4="windows",D4="clang"),AND(F4="windows",G4="clang")),1,0) -> 0 | AC4: =IF(AND(OR(D4="clang",D4="gcc",D4="msvc"),OR(G4="gcc",G4="clang",G4="msvc")),1,0) -> 0 | AD4: =IF(AND(OR(D4="go",D4="tgo"),OR(G4="go",G4="tgo")),1,0) -> 0 | AE4: =IF(AND(OR(D4="rs-pure",D4="rs-sys"),OR(G4="rs-pure",G4="rs-sys")),1,0) -> 0 | AF4: =IF(C4=F4,1,0) -> 1 | AG4: =IF(B4=E4,1,0) -> 1 | AH4: =IF(SUM(AC4:AE4)=1,1,0) -> 0 | AI4: =IF(OR(AND($D4=AI$1,$G4=AI$2),AND($D4=AI$2,$G4=AI$1)),1,0) -> 0 | AJ4: =IF(OR(AND($D4=AJ$1,$G4=AJ$2),AND($D4=AJ$2,$G4=AJ$1)),1,0) -> 0 | AK4: =IF(OR(AND($D4=AK$1,$G4=AK$2),AND($D4=AK$2,$G4=AK$1)),1,0) -> 0 | AL4: =IF(OR(AND($D4=AL$1,$G4=AL$2),AND($D4=AL$2,$G4=AL$1)),1,0) -> 0 | AM4: =IF(OR(AND($D4=AM$1,$G4=AM$2),AND($D4=AM$2,$G4=AM$1)),1,0) -> 0 | AN4: =IF(OR(AND($D4=AN$1,$G4=AN$2),AND($D4=AN$2,$G4=AN$1)),1,0) -> 0 | AO4: =IF(OR(AND($D4=AO$1,$G4=AO$2),AND($D4=AO$2,$G4=AO$1)),1,0) -> 0 | AP4: =IF(OR(AND($D4=AP$1,$G4=AP$2),AND($D4=AP$2,$G4=AP$1)),1,0) -> 0 | ... AW4: =IF(OR(AND($D4=AW$1,$G4=AW$2),AND($D4=AW$2,$G4=AW$1)),1,0) -> 0 | AX4: =IF(OR(AND($C4=AX$1,$F4=AX$2),AND($C4=AX$2,$F4=AX$1)),1,0) -> 0 | AY4: =IF(OR(AND($C4=AY$1,$F4=AY$2),AND($C4=AY$2,$F4=AY$1)),1,0) -> 0 | AZ4: =IF(OR(AND($C4=AZ$1,$F4=AZ$2),AND($C4=AZ$2,$F4=AZ$1)),1,0) -> 0 | BA4: =IF(SUM(AI4:AQ4)=1,1,0) -> 0 | BB4: =IF(OR(C4="windows",F4="windows"),1,0) -> 0
A5: 2 | B5: amd64 | C5: darwin | D5: clang | E5: amd64 | F5: darwin | G5: rs-pure | H5: 0.017138463 | I5: 0.016460982 | J5: 0.014517384 | K5: 0.014941893 | L5: 0.010991525 | M5: 0.0084790216 | N5: 0.018458834 | O5: 0.01175349 | P5: =IF(OR(AND($C5="linux",$D5="clang"),AND($F5="linux",$G5="clang")),1,0) -> 0 | Q5: =IF(OR(AND($C5="linux",$D5="gcc"),AND($F5="linux",$G5="gcc")),1,0) -> 0 | R5: =IF(OR(AND($C5="linux",$D5="go"),AND($F5="linux",$G5="go")),1,0) -> 0 | S5: =IF(OR(AND($C5="linux",$D5="tgo"),AND($F5="linux",$G5="tgo")),1,0) -> 0 | T5: =IF(OR(AND($C5="darwin",$D5="clang"),AND($F5="darwin",$G5="clang")),1,0) -> 1 | U5: =IF(OR(AND($C5="darwin",$D5="gcc"),AND($F5="darwin",$G5="gcc")),1,0) -> 0 | V5: =IF(OR(AND($C5="darwin",$D5="go"),AND($F5="darwin",$G5="go")),1,0) -> 0 | W5: =IF(OR(AND($C5="darwin",$D5="tgo"),AND($F5="darwin",$G5="tgo")),1,0) -> 0 | X5: =IF(OR(AND($C5="windows",$D5="clang"),AND($F5="windows",$G5="clang")),1,0) -> 0 | Y5: =IF(OR(AND($C5="windows",$D5="gcc"),AND($F5="windows",$G5="gcc")),1,0) -> 0 | Z5: =IF(OR(AND($C5="windows",$D5="msvc"),AND($F5="windows",$G5="msvc")),1,0) -> 0 | AA5: =IF(OR(AND($C5="windows",$D5="go"),AND($F5="windows",$G5="go")),1,0) -> 0 | AB5: =IF(AND(AND(C5="windows",D5="clang"),AND(F5="windows",G5="clang")),1,0) -> 0 | AC5: =IF(AND(OR(D5="clang",D5="gcc",D5="msvc"),OR(G5="gcc",G5="clang",G5="msvc")),1,0) -> 0 | AD5: =IF(AND(OR(D5="go",D5="tgo"),OR(G5="go",G5="tgo")),1,0) -> 0 | AE5: =IF(AND(OR(D5="rs-pure",D5="rs-sys"),OR(G5="rs-pure",G5="rs-sys")),1,0) -> 0 | AF5: =IF(C5=F5,1,0) -> 1 | AG5: =IF(B5=E5,1,0) -> 1 | AH5: =IF(SUM(AC5:AE5)=1,1,0) -> 0 | AI5: =IF(OR(AND($D5=AI$1,$G5=AI$2),AND($D5=AI$2,$G5=AI$1)),1,0) -> 0 | AJ5: =IF(OR(AND($D5=AJ$1,$G5=AJ$2),AND($D5=AJ$2,$G5=AJ$1)),1,0) -> 0 | AK5: =IF(OR(AND($D5=AK$1,$G5=AK$2),AND($D5=AK$2,$G5=AK$1)),1,0) -> 0 | AL5: =IF(OR(AND($D5=AL$1,$G5=AL$2),AND($D5=AL$2,$G5=AL$1)),1,0) -> 0 | AM5: =IF(OR(AND($D5=AM$1,$G5=AM$2),AND($D5=AM$2,$G5=AM$1)),1,0) -> 0 | AN5: =IF(OR(AND($D5=AN$1,$G5=AN$2),AND($D5=AN$2,$G5=AN$1)),1,0) -> 1 | AO5: =IF(OR(AND($D5=AO$1,$G5=AO$2),AND($D5=AO$2,$G5=AO$1)),1,0) -> 0 | AP5: =IF(OR(AND($D5=AP$1,$G5=AP$2),AND($D5=AP$2,$G5=AP$1)),1,0) -> 0 | ... AW5: =IF(OR(AND($D5=AW$1,$G5=AW$2),AND($D5=AW$2,$G5=AW$1)),1,0) -> 0 | AX5: =IF(OR(AND($C5=AX$1,$F5=AX$2),AND($C5=AX$2,$F5=AX$1)),1,0) -> 0 | AY5: =IF(OR(AND($C5=AY$1,$F5=AY$2),AND($C5=AY$2,$F5=AY$1)),1,0) -> 0 | AZ5: =IF(OR(AND($C5=AZ$1,$F5=AZ$2),AND($C5=AZ$2,$F5=AZ$1)),1,0) -> 0 | BA5: =IF(SUM(AI5:AQ5)=1,1,0) -> 1 | BB5: =IF(OR(C5="windows",F5="windows"),1,0) -> 0
A6: 3 | B6: amd64 | C6: darwin | D6: clang | E6: amd64 | F6: darwin | G6: rs-sys | H6: 0.017365555 | I6: 0.016767946 | J6: 0.014704665 | K6: 0.015291196 | L6: 0.011177836 | M6: 0.0086066648 | N6: 0.018699911 | O6: 0.011920467 | P6: =IF(OR(AND($C6="linux",$D6="clang"),AND($F6="linux",$G6="clang")),1,0) -> 0 | Q6: =IF(OR(AND($C6="linux",$D6="gcc"),AND($F6="linux",$G6="gcc")),1,0) -> 0 | R6: =IF(OR(AND($C6="linux",$D6="go"),AND($F6="linux",$G6="go")),1,0) -> 0 | S6: =IF(OR(AND($C6="linux",$D6="tgo"),AND($F6="linux",$G6="tgo")),1,0) -> 0 | T6: =IF(OR(AND($C6="darwin",$D6="clang"),AND($F6="darwin",$G6="clang")),1,0) -> 1 | U6: =IF(OR(AND($C6="darwin",$D6="gcc"),AND($F6="darwin",$G6="gcc")),1,0) -> 0 | V6: =IF(OR(AND($C6="darwin",$D6="go"),AND($F6="darwin",$G6="go")),1,0) -> 0 | W6: =IF(OR(AND($C6="darwin",$D6="tgo"),AND($F6="darwin",$G6="tgo")),1,0) -> 0 | X6: =IF(OR(AND($C6="windows",$D6="clang"),AND($F6="windows",$G6="clang")),1,0) -> 0 | Y6: =IF(OR(AND($C6="windows",$D6="gcc"),AND($F6="windows",$G6="gcc")),1,0) -> 0 | Z6: =IF(OR(AND($C6="windows",$D6="msvc"),AND($F6="windows",$G6="msvc")),1,0) -> 0 | AA6: =IF(OR(AND($C6="windows",$D6="go"),AND($F6="windows",$G6="go")),1,0) -> 0 | AB6: =IF(AND(AND(C6="windows",D6="clang"),AND(F6="windows",G6="clang")),1,0) -> 0 | AC6: =IF(AND(OR(D6="clang",D6="gcc",D6="msvc"),OR(G6="gcc",G6="clang",G6="msvc")),1,0) -> 0 | AD6: =IF(AND(OR(D6="go",D6="tgo"),OR(G6="go",G6="tgo")),1,0) -> 0 | AE6: =IF(AND(OR(D6="rs-pure",D6="rs-sys"),OR(G6="rs-pure",G6="rs-sys")),1,0) -> 0 | AF6: =IF(C6=F6,1,0) -> 1 | AG6: =IF(B6=E6,1,0) -> 1 | AH6: =IF(SUM(AC6:AE6)=1,1,0) -> 0 | AI6: =IF(OR(AND($D6=AI$1,$G6=AI$2),AND($D6=AI$2,$G6=AI$1)),1,0) -> 0 | AJ6: =IF(OR(AND($D6=AJ$1,$G6=AJ$2),AND($D6=AJ$2,$G6=AJ$1)),1,0) -> 1 | AK6: =IF(OR(AND($D6=AK$1,$G6=AK$2),AND($D6=AK$2,$G6=AK$1)),1,0) -> 0 | AL6: =IF(OR(AND($D6=AL$1,$G6=AL$2),AND($D6=AL$2,$G6=AL$1)),1,0) -> 0 | AM6: =IF(OR(AND($D6=AM$1,$G6=AM$2),AND($D6=AM$2,$G6=AM$1)),1,0) -> 0 | AN6: =IF(OR(AND($D6=AN$1,$G6=AN$2),AND($D6=AN$2,$G6=AN$1)),1,0) -> 0 | AO6: =IF(OR(AND($D6=AO$1,$G6=AO$2),AND($D6=AO$2,$G6=AO$1)),1,0) -> 0 | AP6: =IF(OR(AND($D6=AP$1,$G6=AP$2),AND($D6=AP$2,$G6=AP$1)),1,0) -> 0 | ... AW6: =IF(OR(AND($D6=AW$1,$G6=AW$2),AND($D6=AW$2,$G6=AW$1)),1,0) -> 0 | AX6: =IF(OR(AND($C6=AX$1,$F6=AX$2),AND($C6=AX$2,$F6=AX$1)),1,0) -> 0 | AY6: =IF(OR(AND($C6=AY$1,$F6=AY$2),AND($C6=AY$2,$F6=AY$1)),1,0) -> 0 | AZ6: =IF(OR(AND($C6=AZ$1,$F6=AZ$2),AND($C6=AZ$2,$F6=AZ$1)),1,0) -> 0 | BA6: =IF(SUM(AI6:AQ6)=1,1,0) -> 1 | BB6: =IF(OR(C6="windows",F6="windows"),1,0) -> 0
A7: 4 | B7: amd64 | C7: darwin | D7: clang | E7: amd64 | F7: darwin | G7: tgo | H7: 0.10046842 | I7: 0.094549471 | J7: 0.081989628 | K7: 0.084272494 | L7: 0.06092742 | M7: 0.046253487 | N7: 0.109375 | O7: 0.06462911 | P7: =IF(OR(AND($C7="linux",$D7="clang"),AND($F7="linux",$G7="clang")),1,0) -> 0 | Q7: =IF(OR(AND($C7="linux",$D7="gcc"),AND($F7="linux",$G7="gcc")),1,0) -> 0 | R7: =IF(OR(AND($C7="linux",$D7="go"),AND($F7="linux",$G7="go")),1,0) -> 0 | S7: =IF(OR(AND($C7="linux",$D7="tgo"),AND($F7="linux",$G7="tgo")),1,0) -> 0 | T7: =IF(OR(AND($C7="darwin",$D7="clang"),AND($F7="darwin",$G7="clang")),1,0) -> 1 | U7: =IF(OR(AND($C7="darwin",$D7="gcc"),AND($F7="darwin",$G7="gcc")),1,0) -> 0 | V7: =IF(OR(AND($C7="darwin",$D7="go"),AND($F7="darwin",$G7="go")),1,0) -> 0 | W7: =IF(OR(AND($C7="darwin",$D7="tgo"),AND($F7="darwin",$G7="tgo")),1,0) -> 1 | X7: =IF(OR(AND($C7="windows",$D7="clang"),AND($F7="windows",$G7="clang")),1,0) -> 0 | Y7: =IF(OR(AND($C7="windows",$D7="gcc"),AND($F7="windows",$G7="gcc")),1,0) -> 0 | Z7: =IF(OR(AND($C7="windows",$D7="msvc"),AND($F7="windows",$G7="msvc")),1,0) -> 0 | AA7: =IF(OR(AND($C7="windows",$D7="go"),AND($F7="windows",$G7="go")),1,0) -> 0 | AB7: =IF(AND(AND(C7="windows",D7="clang"),AND(F7="windows",G7="clang")),1,0) -> 0 | AC7: =IF(AND(OR(D7="clang",D7="gcc",D7="msvc"),OR(G7="gcc",G7="clang",G7="msvc")),1,0) -> 0 | AD7: =IF(AND(OR(D7="go",D7="tgo"),OR(G7="go",G7="tgo")),1,0) -> 0 | AE7: =IF(AND(OR(D7="rs-pure",D7="rs-sys"),OR(G7="rs-pure",G7="rs-sys")),1,0) -> 0 | AF7: =IF(C7=F7,1,0) -> 1 | AG7: =IF(B7=E7,1,0) -> 1 | AH7: =IF(SUM(AC7:AE7)=1,1,0) -> 0 | AI7: =IF(OR(AND($D7=AI$1,$G7=AI$2),AND($D7=AI$2,$G7=AI$1)),1,0) -> 0 | AJ7: =IF(OR(AND($D7=AJ$1,$G7=AJ$2),AND($D7=AJ$2,$G7=AJ$1)),1,0) -> 0 | AK7: =IF(OR(AND($D7=AK$1,$G7=AK$2),AND($D7=AK$2,$G7=AK$1)),1,0) -> 0 | AL7: =IF(OR(AND($D7=AL$1,$G7=AL$2),AND($D7=AL$2,$G7=AL$1)),1,0) -> 0 | AM7: =IF(OR(AND($D7=AM$1,$G7=AM$2),AND($D7=AM$2,$G7=AM$1)),1,0) -> 0 | AN7: =IF(OR(AND($D7=AN$1,$G7=AN$2),AND($D7=AN$2,$G7=AN$1)),1,0) -> 0 | AO7: =IF(OR(AND($D7=AO$1,$G7=AO$2),AND($D7=AO$2,$G7=AO$1)),1,0) -> 0 | AP7: =IF(OR(AND($D7=AP$1,$G7=AP$2),AND($D7=AP$2,$G7=AP$1)),1,0) -> 0 | ... AW7: =IF(OR(AND($D7=AW$1,$G7=AW$2),AND($D7=AW$2,$G7=AW$1)),1,0) -> 0 | AX7: =IF(OR(AND($C7=AX$1,$F7=AX$2),AND($C7=AX$2,$F7=AX$1)),1,0) -> 0 | AY7: =IF(OR(AND($C7=AY$1,$F7=AY$2),AND($C7=AY$2,$F7=AY$1)),1,0) -> 0 | AZ7: =IF(OR(AND($C7=AZ$1,$F7=AZ$2),AND($C7=AZ$2,$F7=AZ$1)),1,0) -> 0 | BA7: =IF(SUM(AI7:AQ7)=1,1,0) -> 0 | BB7: =IF(OR(C7="windows",F7="windows"),1,0) -> 0
A8: 5 | B8: amd64 | C8: darwin | D8: clang | E8: amd64 | F8: linux | G8: clang | H8: 0.86089428 | I8: 0.87082813 | J8: 0.80004165 | K8: 0.83159857 | L8: 0.77961433 | M8: 0.71281627 | N8: 0.92647059 | O8: 0.76853514 | P8: =IF(OR(AND($C8="linux",$D8="clang"),AND($F8="linux",$G8="clang")),1,0) -> 1 | Q8: =IF(OR(AND($C8="linux",$D8="gcc"),AND($F8="linux",$G8="gcc")),1,0) -> 0 | R8: =IF(OR(AND($C8="linux",$D8="go"),AND($F8="linux",$G8="go")),1,0) -> 0 | S8: =IF(OR(AND($C8="linux",$D8="tgo"),AND($F8="linux",$G8="tgo")),1,0) -> 0 | T8: =IF(OR(AND($C8="darwin",$D8="clang"),AND($F8="darwin",$G8="clang")),1,0) -> 1 | U8: =IF(OR(AND($C8="darwin",$D8="gcc"),AND($F8="darwin",$G8="gcc")),1,0) -> 0 | V8: =IF(OR(AND($C8="darwin",$D8="go"),AND($F8="darwin",$G8="go")),1,0) -> 0 | W8: =IF(OR(AND($C8="darwin",$D8="tgo"),AND($F8="darwin",$G8="tgo")),1,0) -> 0 | X8: =IF(OR(AND($C8="windows",$D8="clang"),AND($F8="windows",$G8="clang")),1,0) -> 0 | Y8: =IF(OR(AND($C8="windows",$D8="gcc"),AND($F8="windows",$G8="gcc")),1,0) -> 0 | Z8: =IF(OR(AND($C8="windows",$D8="msvc"),AND($F8="windows",$G8="msvc")),1,0) -> 0 | AA8: =IF(OR(AND($C8="windows",$D8="go"),AND($F8="windows",$G8="go")),1,0) -> 0 | AB8: =IF(AND(AND(C8="windows",D8="clang"),AND(F8="windows",G8="clang")),1,0) -> 0 | AC8: =IF(AND(OR(D8="clang",D8="gcc",D8="msvc"),OR(G8="gcc",G8="clang",G8="msvc")),1,0) -> 1 | AD8: =IF(AND(OR(D8="go",D8="tgo"),OR(G8="go",G8="tgo")),1,0) -> 0 | AE8: =IF(AND(OR(D8="rs-pure",D8="rs-sys"),OR(G8="rs-pure",G8="rs-sys")),1,0) -> 0 | AF8: =IF(C8=F8,1,0) -> 0 | AG8: =IF(B8=E8,1,0) -> 1 | AH8: =IF(SUM(AC8:AE8)=1,1,0) -> 1 | AI8: =IF(OR(AND($D8=AI$1,$G8=AI$2),AND($D8=AI$2,$G8=AI$1)),1,0) -> 0 | AJ8: =IF(OR(AND($D8=AJ$1,$G8=AJ$2),AND($D8=AJ$2,$G8=AJ$1)),1,0) -> 0 | AK8: =IF(OR(AND($D8=AK$1,$G8=AK$2),AND($D8=AK$2,$G8=AK$1)),1,0) -> 0 | AL8: =IF(OR(AND($D8=AL$1,$G8=AL$2),AND($D8=AL$2,$G8=AL$1)),1,0) -> 0 | AM8: =IF(OR(AND($D8=AM$1,$G8=AM$2),AND($D8=AM$2,$G8=AM$1)),1,0) -> 0 | AN8: =IF(OR(AND($D8=AN$1,$G8=AN$2),AND($D8=AN$2,$G8=AN$1)),1,0) -> 0 | AO8: =IF(OR(AND($D8=AO$1,$G8=AO$2),AND($D8=AO$2,$G8=AO$1)),1,0) -> 0 | AP8: =IF(OR(AND($D8=AP$1,$G8=AP$2),AND($D8=AP$2,$G8=AP$1)),1,0) -> 0 | ... AW8: =IF(OR(AND($D8=AW$1,$G8=AW$2),AND($D8=AW$2,$G8=AW$1)),1,0) -> 0 | AX8: =IF(OR(AND($C8=AX$1,$F8=AX$2),AND($C8=AX$2,$F8=AX$1)),1,0) -> 1 | AY8: =IF(OR(AND($C8=AY$1,$F8=AY$2),AND($C8=AY$2,$F8=AY$1)),1,0) -> 0 | AZ8: =IF(OR(AND($C8=AZ$1,$F8=AZ$2),AND($C8=AZ$2,$F8=AZ$1)),1,0) -> 0 | BA8: =IF(SUM(AI8:AQ8)=1,1,0) -> 0 | BB8: =IF(OR(C8="windows",F8="windows"),1,0) -> 0
A9: 6 | B9: amd64 | C9: darwin | D9: clang | E9: amd64 | F9: linux | G9: gcc | H9: 0.75689193 | I9: 0.71422023 | J9: 0.60045905 | K9: 0.63332271 | L9: 0.48998006 | M9: 0.38090811 | N9: 0.84 | O9: 0.49542535 | P9: =IF(OR(AND($C9="linux",$D9="clang"),AND($F9="linux",$G9="clang")),1,0) -> 0 | Q9: =IF(OR(AND($C9="linux",$D9="gcc"),AND($F9="linux",$G9="gcc")),1,0) -> 1 | R9: =IF(OR(AND($C9="linux",$D9="go"),AND($F9="linux",$G9="go")),1,0) -> 0 | S9: =IF(OR(AND($C9="linux",$D9="tgo"),AND($F9="linux",$G9="tgo")),1,0) -> 0 | T9: =IF(OR(AND($C9="darwin",$D9="clang"),AND($F9="darwin",$G9="clang")),1,0) -> 1 | U9: =IF(OR(AND($C9="darwin",$D9="gcc"),AND($F9="darwin",$G9="gcc")),1,0) -> 0 | V9: =IF(OR(AND($C9="darwin",$D9="go"),AND($F9="darwin",$G9="go")),1,0) -> 0 | W9: =IF(OR(AND($C9="darwin",$D9="tgo"),AND($F9="darwin",$G9="tgo")),1,0) -> 0 | X9: =IF(OR(AND($C9="windows",$D9="clang"),AND($F9="windows",$G9="clang")),1,0) -> 0 | Y9: =IF(OR(AND($C9="windows",$D9="gcc"),AND($F9="windows",$G9="gcc")),1,0) -> 0 | Z9: =IF(OR(AND($C9="windows",$D9="msvc"),AND($F9="windows",$G9="msvc")),1,0) -> 0 | AA9: =IF(OR(AND($C9="windows",$D9="go"),AND($F9="windows",$G9="go")),1,0) -> 0 | AB9: =IF(AND(AND(C9="windows",D9="clang"),AND(F9="windows",G9="clang")),1,0) -> 0 | AC9: =IF(AND(OR(D9="clang",D9="gcc",D9="msvc"),OR(G9="gcc",G9="clang",G9="msvc")),1,0) -> 1 | AD9: =IF(AND(OR(D9="go",D9="tgo"),OR(G9="go",G9="tgo")),1,0) -> 0 | AE9: =IF(AND(OR(D9="rs-pure",D9="rs-sys"),OR(G9="rs-pure",G9="rs-sys")),1,0) -> 0 | AF9: =IF(C9=F9,1,0) -> 0 | AG9: =IF(B9=E9,1,0) -> 1 | AH9: =IF(SUM(AC9:AE9)=1,1,0) -> 1 | AI9: =IF(OR(AND($D9=AI$1,$G9=AI$2),AND($D9=AI$2,$G9=AI$1)),1,0) -> 0 | AJ9: =IF(OR(AND($D9=AJ$1,$G9=AJ$2),AND($D9=AJ$2,$G9=AJ$1)),1,0) -> 0 | AK9: =IF(OR(AND($D9=AK$1,$G9=AK$2),AND($D9=AK$2,$G9=AK$1)),1,0) -> 0 | AL9: =IF(OR(AND($D9=AL$1,$G9=AL$2),AND($D9=AL$2,$G9=AL$1)),1,0) -> 0 | AM9: =IF(OR(AND($D9=AM$1,$G9=AM$2),AND($D9=AM$2,$G9=AM$1)),1,0) -> 0 | AN9: =IF(OR(AND($D9=AN$1,$G9=AN$2),AND($D9=AN$2,$G9=AN$1)),1,0) -> 0 | AO9: =IF(OR(AND($D9=AO$1,$G9=AO$2),AND($D9=AO$2,$G9=AO$1)),1,0) -> 0 | AP9: =IF(OR(AND($D9=AP$1,$G9=AP$2),AND($D9=AP$2,$G9=AP$1)),1,0) -> 0 | ... AW9: =IF(OR(AND($D9=AW$1,$G9=AW$2),AND($D9=AW$2,$G9=AW$1)),1,0) -> 0 | AX9: =IF(OR(AND($C9=AX$1,$F9=AX$2),AND($C9=AX$2,$F9=AX$1)),1,0) -> 1 | AY9: =IF(OR(AND($C9=AY$1,$F9=AY$2),AND($C9=AY$2,$F9=AY$1)),1,0) -> 0 | AZ9: =IF(OR(AND($C9=AZ$1,$F9=AZ$2),AND($C9=AZ$2,$F9=AZ$1)),1,0) -> 0 | BA9: =IF(SUM(AI9:AQ9)=1,1,0) -> 0 | BB9: =IF(OR(C9="windows",F9="windows"),1,0) -> 0
A10: 7 | B10: amd64 | C10: darwin | D10: clang | E10: amd64 | F10: linux | G10: go | H10: 0.022834531 | I10: 0.021325377 | J10: 0.018955056 | K10: 0.019055516 | L10: 0.014236759 | M10: 0.011106685 | N10: 0.024494557 | O10: 0.015363697 | P10: =IF(OR(AND($C10="linux",$D10="clang"),AND($F10="linux",$G10="clang")),1,0) -> 0 | Q10: =IF(OR(AND($C10="linux",$D10="gcc"),AND($F10="linux",$G10="gcc")),1,0) -> 0 | R10: =IF(OR(AND($C10="linux",$D10="go"),AND($F10="linux",$G10="go")),1,0) -> 1 | S10: =IF(OR(AND($C10="linux",$D10="tgo"),AND($F10="linux",$G10="tgo")),1,0) -> 0 | T10: =IF(OR(AND($C10="darwin",$D10="clang"),AND($F10="darwin",$G10="clang")),1,0) -> 1 | U10: =IF(OR(AND($C10="darwin",$D10="gcc"),AND($F10="darwin",$G10="gcc")),1,0) -> 0 | V10: =IF(OR(AND($C10="darwin",$D10="go"),AND($F10="darwin",$G10="go")),1,0) -> 0 | W10: =IF(OR(AND($C10="darwin",$D10="tgo"),AND($F10="darwin",$G10="tgo")),1,0) -> 0 | X10: =IF(OR(AND($C10="windows",$D10="clang"),AND($F10="windows",$G10="clang")),1,0) -> 0 | Y10: =IF(OR(AND($C10="windows",$D10="gcc"),AND($F10="windows",$G10="gcc")),1,0) -> 0 | Z10: =IF(OR(AND($C10="windows",$D10="msvc"),AND($F10="windows",$G10="msvc")),1,0) -> 0 | AA10: =IF(OR(AND($C10="windows",$D10="go"),AND($F10="windows",$G10="go")),1,0) -> 0 | AB10: =IF(AND(AND(C10="windows",D10="clang"),AND(F10="windows",G10="clang")),1,0) -> 0 | AC10: =IF(AND(OR(D10="clang",D10="gcc",D10="msvc"),OR(G10="gcc",G10="clang",G10="msvc")),1,0) -> 0 | AD10: =IF(AND(OR(D10="go",D10="tgo"),OR(G10="go",G10="tgo")),1,0) -> 0 | AE10: =IF(AND(OR(D10="rs-pure",D10="rs-sys"),OR(G10="rs-pure",G10="rs-sys")),1,0) -> 0 | AF10: =IF(C10=F10,1,0) -> 0 | AG10: =IF(B10=E10,1,0) -> 1 | AH10: =IF(SUM(AC10:AE10)=1,1,0) -> 0 | AI10: =IF(OR(AND($D10=AI$1,$G10=AI$2),AND($D10=AI$2,$G10=AI$1)),1,0) -> 0 | AJ10: =IF(OR(AND($D10=AJ$1,$G10=AJ$2),AND($D10=AJ$2,$G10=AJ$1)),1,0) -> 0 | AK10: =IF(OR(AND($D10=AK$1,$G10=AK$2),AND($D10=AK$2,$G10=AK$1)),1,0) -> 0 | AL10: =IF(OR(AND($D10=AL$1,$G10=AL$2),AND($D10=AL$2,$G10=AL$1)),1,0) -> 0 | AM10: =IF(OR(AND($D10=AM$1,$G10=AM$2),AND($D10=AM$2,$G10=AM$1)),1,0) -> 0 | AN10: =IF(OR(AND($D10=AN$1,$G10=AN$2),AND($D10=AN$2,$G10=AN$1)),1,0) -> 0 | AO10: =IF(OR(AND($D10=AO$1,$G10=AO$2),AND($D10=AO$2,$G10=AO$1)),1,0) -> 0 | AP10: =IF(OR(AND($D10=AP$1,$G10=AP$2),AND($D10=AP$2,$G10=AP$1)),1,0) -> 0 | ... AW10: =IF(OR(AND($D10=AW$1,$G10=AW$2),AND($D10=AW$2,$G10=AW$1)),1,0) -> 0 | AX10: =IF(OR(AND($C10=AX$1,$F10=AX$2),AND($C10=AX$2,$F10=AX$1)),1,0) -> 1 | AY10: =IF(OR(AND($C10=AY$1,$F10=AY$2),AND($C10=AY$2,$F10=AY$1)),1,0) -> 0 | AZ10: =IF(OR(AND($C10=AZ$1,$F10=AZ$2),AND($C10=AZ$2,$F10=AZ$1)),1,0) -> 0 | BA10: =IF(SUM(AI10:AQ10)=1,1,0) -> 0 | BB10: =IF(OR(C10="windows",F10="windows"),1,0) -> 0
A11: 8 | B11: amd64 | C11: darwin | D11: clang | E11: amd64 | F11: linux | G11: rs-pure | H11: 0.017044783 | I11: 0.016495724 | J11: 0.014598348 | K11: 0.014951959 | L11: 0.011102903 | M11: 0.0087624143 | N11: 0.018600531 | O11: 0.011873762 | P11: =IF(OR(AND($C11="linux",$D11="clang"),AND($F11="linux",$G11="clang")),1,0) -> 0 | Q11: =IF(OR(AND($C11="linux",$D11="gcc"),AND($F11="linux",$G11="gcc")),1,0) -> 0 | R11: =IF(OR(AND($C11="linux",$D11="go"),AND($F11="linux",$G11="go")),1,0) -> 0 | S11: =IF(OR(AND($C11="linux",$D11="tgo"),AND($F11="linux",$G11="tgo")),1,0) -> 0 | T11: =IF(OR(AND($C11="darwin",$D11="clang"),AND($F11="darwin",$G11="clang")),1,0) -> 1 | U11: =IF(OR(AND($C11="darwin",$D11="gcc"),AND($F11="darwin",$G11="gcc")),1,0) -> 0 | V11: =IF(OR(AND($C11="darwin",$D11="go"),AND($F11="darwin",$G11="go")),1,0) -> 0 | W11: =IF(OR(AND($C11="darwin",$D11="tgo"),AND($F11="darwin",$G11="tgo")),1,0) -> 0 | X11: =IF(OR(AND($C11="windows",$D11="clang"),AND($F11="windows",$G11="clang")),1,0) -> 0 | Y11: =IF(OR(AND($C11="windows",$D11="gcc"),AND($F11="windows",$G11="gcc")),1,0) -> 0 | Z11: =IF(OR(AND($C11="windows",$D11="msvc"),AND($F11="windows",$G11="msvc")),1,0) -> 0 | AA11: =IF(OR(AND($C11="windows",$D11="go"),AND($F11="windows",$G11="go")),1,0) -> 0 | AB11: =IF(AND(AND(C11="windows",D11="clang"),AND(F11="windows",G11="clang")),1,0) -> 0 | AC11: =IF(AND(OR(D11="clang",D11="gcc",D11="msvc"),OR(G11="gcc",G11="clang",G11="msvc")),1,0) -> 0 | AD11: =IF(AND(OR(D11="go",D11="tgo"),OR(G11="go",G11="tgo")),1,0) -> 0 | AE11: =IF(AND(OR(D11="rs-pure",D11="rs-sys"),OR(G11="rs-pure",G11="rs-sys")),1,0) -> 0 | AF11: =IF(C11=F11,1,0) -> 0 | AG11: =IF(B11=E11,1,0) -> 1 | AH11: =IF(SUM(AC11:AE11)=1,1,0) -> 0 | AI11: =IF(OR(AND($D11=AI$1,$G11=AI$2),AND($D11=AI$2,$G11=AI$1)),1,0) -> 0 | AJ11: =IF(OR(AND($D11=AJ$1,$G11=AJ$2),AND($D11=AJ$2,$G11=AJ$1)),1,0) -> 0 | AK11: =IF(OR(AND($D11=AK$1,$G11=AK$2),AND($D11=AK$2,$G11=AK$1)),1,0) -> 0 | AL11: =IF(OR(AND($D11=AL$1,$G11=AL$2),AND($D11=AL$2,$G11=AL$1)),1,0) -> 0 | AM11: =IF(OR(AND($D11=AM$1,$G11=AM$2),AND($D11=AM$2,$G11=AM$1)),1,0) -> 0 | AN11: =IF(OR(AND($D11=AN$1,$G11=AN$2),AND($D11=AN$2,$G11=AN$1)),1,0) -> 1 | AO11: =IF(OR(AND($D11=AO$1,$G11=AO$2),AND($D11=AO$2,$G11=AO$1)),1,0) -> 0 | AP11: =IF(OR(AND($D11=AP$1,$G11=AP$2),AND($D11=AP$2,$G11=AP$1)),1,0) -> 0 | ... AW11: =IF(OR(AND($D11=AW$1,$G11=AW$2),AND($D11=AW$2,$G11=AW$1)),1,0) -> 0 | AX11: =IF(OR(AND($C11=AX$1,$F11=AX$2),AND($C11=AX$2,$F11=AX$1)),1,0) -> 1 | AY11: =IF(OR(AND($C11=AY$1,$F11=AY$2),AND($C11=AY$2,$F11=AY$1)),1,0) -> 0 | AZ11: =IF(OR(AND($C11=AZ$1,$F11=AZ$2),AND($C11=AZ$2,$F11=AZ$1)),1,0) -> 0 | BA11: =IF(SUM(AI11:AQ11)=1,1,0) -> 1 | BB11: =IF(OR(C11="windows",F11="windows"),1,0) -> 0
A12: 9 | B12: amd64 | C12: darwin | D12: clang | E12: amd64 | F12: linux | G12: rs-sys | H12: 0.017317207 | I12: 0.016818624 | J12: 0.014836794 | K12: 0.015298534 | L12: 0.011346477 | M12: 0.0089785003 | N12: 0.018879233 | O12: 0.012128004 | P12: =IF(OR(AND($C12="linux",$D12="clang"),AND($F12="linux",$G12="clang")),1,0) -> 0 | Q12: =IF(OR(AND($C12="linux",$D12="gcc"),AND($F12="linux",$G12="gcc")),1,0) -> 0 | R12: =IF(OR(AND($C12="linux",$D12="go"),AND($F12="linux",$G12="go")),1,0) -> 0 | S12: =IF(OR(AND($C12="linux",$D12="tgo"),AND($F12="linux",$G12="tgo")),1,0) -> 0 | T12: =IF(OR(AND($C12="darwin",$D12="clang"),AND($F12="darwin",$G12="clang")),1,0) -> 1 | U12: =IF(OR(AND($C12="darwin",$D12="gcc"),AND($F12="darwin",$G12="gcc")),1,0) -> 0 | V12: =IF(OR(AND($C12="darwin",$D12="go"),AND($F12="darwin",$G12="go")),1,0) -> 0 | W12: =IF(OR(AND($C12="darwin",$D12="tgo"),AND($F12="darwin",$G12="tgo")),1,0) -> 0 | X12: =IF(OR(AND($C12="windows",$D12="clang"),AND($F12="windows",$G12="clang")),1,0) -> 0 | Y12: =IF(OR(AND($C12="windows",$D12="gcc"),AND($F12="windows",$G12="gcc")),1,0) -> 0 | Z12: =IF(OR(AND($C12="windows",$D12="msvc"),AND($F12="windows",$G12="msvc")),1,0) -> 0 | AA12: =IF(OR(AND($C12="windows",$D12="go"),AND($F12="windows",$G12="go")),1,0) -> 0 | AB12: =IF(AND(AND(C12="windows",D12="clang"),AND(F12="windows",G12="clang")),1,0) -> 0 | AC12: =IF(AND(OR(D12="clang",D12="gcc",D12="msvc"),OR(G12="gcc",G12="clang",G12="msvc")),1,0) -> 0 | AD12: =IF(AND(OR(D12="go",D12="tgo"),OR(G12="go",G12="tgo")),1,0) -> 0 | AE12: =IF(AND(OR(D12="rs-pure",D12="rs-sys"),OR(G12="rs-pure",G12="rs-sys")),1,0) -> 0 | AF12: =IF(C12=F12,1,0) -> 0 | AG12: =IF(B12=E12,1,0) -> 1 | AH12: =IF(SUM(AC12:AE12)=1,1,0) -> 0 | AI12: =IF(OR(AND($D12=AI$1,$G12=AI$2),AND($D12=AI$2,$G12=AI$1)),1,0) -> 0 | AJ12: =IF(OR(AND($D12=AJ$1,$G12=AJ$2),AND($D12=AJ$2,$G12=AJ$1)),1,0) -> 1 | AK12: =IF(OR(AND($D12=AK$1,$G12=AK$2),AND($D12=AK$2,$G12=AK$1)),1,0) -> 0 | AL12: =IF(OR(AND($D12=AL$1,$G12=AL$2),AND($D12=AL$2,$G12=AL$1)),1,0) -> 0 | AM12: =IF(OR(AND($D12=AM$1,$G12=AM$2),AND($D12=AM$2,$G12=AM$1)),1,0) -> 0 | AN12: =IF(OR(AND($D12=AN$1,$G12=AN$2),AND($D12=AN$2,$G12=AN$1)),1,0) -> 0 | AO12: =IF(OR(AND($D12=AO$1,$G12=AO$2),AND($D12=AO$2,$G12=AO$1)),1,0) -> 0 | AP12: =IF(OR(AND($D12=AP$1,$G12=AP$2),AND($D12=AP$2,$G12=AP$1)),1,0) -> 0 | ... AW12: =IF(OR(AND($D12=AW$1,$G12=AW$2),AND($D12=AW$2,$G12=AW$1)),1,0) -> 0 | AX12: =IF(OR(AND($C12=AX$1,$F12=AX$2),AND($C12=AX$2,$F12=AX$1)),1,0) -> 1 | AY12: =IF(OR(AND($C12=AY$1,$F12=AY$2),AND($C12=AY$2,$F12=AY$1)),1,0) -> 0 | AZ12: =IF(OR(AND($C12=AZ$1,$F12=AZ$2),AND($C12=AZ$2,$F12=AZ$1)),1,0) -> 0 | BA12: =IF(SUM(AI12:AQ12)=1,1,0) -> 1 | BB12: =IF(OR(C12="windows",F12="windows"),1,0) -> 0
A13: 10 | B13: amd64 | C13: darwin | D13: clang | E13: amd64 | F13: linux | G13: tgo | H13: 0.082213811 | I13: 0.078161128 | J13: 0.066149057 | K13: 0.069664722 | L13: 0.049887323 | M13: 0.038262812 | N13: 0.089871612 | O13: 0.05192047 | P13: =IF(OR(AND($C13="linux",$D13="clang"),AND($F13="linux",$G13="clang")),1,0) -> 0 | Q13: =IF(OR(AND($C13="linux",$D13="gcc"),AND($F13="linux",$G13="gcc")),1,0) -> 0 | R13: =IF(OR(AND($C13="linux",$D13="go"),AND($F13="linux",$G13="go")),1,0) -> 0 | S13: =IF(OR(AND($C13="linux",$D13="tgo"),AND($F13="linux",$G13="tgo")),1,0) -> 1 | T13: =IF(OR(AND($C13="darwin",$D13="clang"),AND($F13="darwin",$G13="clang")),1,0) -> 1 | U13: =IF(OR(AND($C13="darwin",$D13="gcc"),AND($F13="darwin",$G13="gcc")),1,0) -> 0 | V13: =IF(OR(AND($C13="darwin",$D13="go"),AND($F13="darwin",$G13="go")),1,0) -> 0 | W13: =IF(OR(AND($C13="darwin",$D13="tgo"),AND($F13="darwin",$G13="tgo")),1,0) -> 0 | X13: =IF(OR(AND($C13="windows",$D13="clang"),AND($F13="windows",$G13="clang")),1,0) -> 0 | Y13: =IF(OR(AND($C13="windows",$D13="gcc"),AND($F13="windows",$G13="gcc")),1,0) -> 0 | Z13: =IF(OR(AND($C13="windows",$D13="msvc"),AND($F13="windows",$G13="msvc")),1,0) -> 0 | AA13: =IF(OR(AND($C13="windows",$D13="go"),AND($F13="windows",$G13="go")),1,0) -> 0 | AB13: =IF(AND(AND(C13="windows",D13="clang"),AND(F13="windows",G13="clang")),1,0) -> 0 | AC13: =IF(AND(OR(D13="clang",D13="gcc",D13="msvc"),OR(G13="gcc",G13="clang",G13="msvc")),1,0) -> 0 | AD13: =IF(AND(OR(D13="go",D13="tgo"),OR(G13="go",G13="tgo")),1,0) -> 0 | AE13: =IF(AND(OR(D13="rs-pure",D13="rs-sys"),OR(G13="rs-pure",G13="rs-sys")),1,0) -> 0 | AF13: =IF(C13=F13,1,0) -> 0 | AG13: =IF(B13=E13,1,0) -> 1 | AH13: =IF(SUM(AC13:AE13)=1,1,0) -> 0 | AI13: =IF(OR(AND($D13=AI$1,$G13=AI$2),AND($D13=AI$2,$G13=AI$1)),1,0) -> 0 | AJ13: =IF(OR(AND($D13=AJ$1,$G13=AJ$2),AND($D13=AJ$2,$G13=AJ$1)),1,0) -> 0 | AK13: =IF(OR(AND($D13=AK$1,$G13=AK$2),AND($D13=AK$2,$G13=AK$1)),1,0) -> 0 | AL13: =IF(OR(AND($D13=AL$1,$G13=AL$2),AND($D13=AL$2,$G13=AL$1)),1,0) -> 0 | AM13: =IF(OR(AND($D13=AM$1,$G13=AM$2),AND($D13=AM$2,$G13=AM$1)),1,0) -> 0 | AN13: =IF(OR(AND($D13=AN$1,$G13=AN$2),AND($D13=AN$2,$G13=AN$1)),1,0) -> 0 | AO13: =IF(OR(AND($D13=AO$1,$G13=AO$2),AND($D13=AO$2,$G13=AO$1)),1,0) -> 0 | AP13: =IF(OR(AND($D13=AP$1,$G13=AP$2),AND($D13=AP$2,$G13=AP$1)),1,0) -> 0 | ... AW13: =IF(OR(AND($D13=AW$1,$G13=AW$2),AND($D13=AW$2,$G13=AW$1)),1,0) -> 0 | AX13: =IF(OR(AND($C13=AX$1,$F13=AX$2),AND($C13=AX$2,$F13=AX$1)),1,0) -> 1 | AY13: =IF(OR(AND($C13=AY$1,$F13=AY$2),AND($C13=AY$2,$F13=AY$1)),1,0) -> 0 | AZ13: =IF(OR(AND($C13=AZ$1,$F13=AZ$2),AND($C13=AZ$2,$F13=AZ$1)),1,0) -> 0 | BA13: =IF(SUM(AI13:AQ13)=1,1,0) -> 0 | BB13: =IF(OR(C13="windows",F13="windows"),1,0) -> 0
A14: 11 | B14: amd64 | C14: darwin | D14: clang | E14: amd64 | F14: windows | G14: clang | H14: 0.028773255 | I14: 0.028485571 | J14: 0.025539686 | K14: 0.027177034 | L14: 0.023378066 | M14: 0.020237613 | N14: 0.030028599 | O14: 0.023403063 | P14: =IF(OR(AND($C14="linux",$D14="clang"),AND($F14="linux",$G14="clang")),1,0) -> 0 | Q14: =IF(OR(AND($C14="linux",$D14="gcc"),AND($F14="linux",$G14="gcc")),1,0) -> 0 | R14: =IF(OR(AND($C14="linux",$D14="go"),AND($F14="linux",$G14="go")),1,0) -> 0 | S14: =IF(OR(AND($C14="linux",$D14="tgo"),AND($F14="linux",$G14="tgo")),1,0) -> 0 | T14: =IF(OR(AND($C14="darwin",$D14="clang"),AND($F14="darwin",$G14="clang")),1,0) -> 1 | U14: =IF(OR(AND($C14="darwin",$D14="gcc"),AND($F14="darwin",$G14="gcc")),1,0) -> 0 | V14: =IF(OR(AND($C14="darwin",$D14="go"),AND($F14="darwin",$G14="go")),1,0) -> 0 | W14: =IF(OR(AND($C14="darwin",$D14="tgo"),AND($F14="darwin",$G14="tgo")),1,0) -> 0 | X14: =IF(OR(AND($C14="windows",$D14="clang"),AND($F14="windows",$G14="clang")),1,0) -> 1 | Y14: =IF(OR(AND($C14="windows",$D14="gcc"),AND($F14="windows",$G14="gcc")),1,0) -> 0 | Z14: =IF(OR(AND($C14="windows",$D14="msvc"),AND($F14="windows",$G14="msvc")),1,0) -> 0 | AA14: =IF(OR(AND($C14="windows",$D14="go"),AND($F14="windows",$G14="go")),1,0) -> 0 | AB14: =IF(AND(AND(C14="windows",D14="clang"),AND(F14="windows",G14="clang")),1,0) -> 0 | AC14: =IF(AND(OR(D14="clang",D14="gcc",D14="msvc"),OR(G14="gcc",G14="clang",G14="msvc")),1,0) -> 1 | AD14: =IF(AND(OR(D14="go",D14="tgo"),OR(G14="go",G14="tgo")),1,0) -> 0 | AE14: =IF(AND(OR(D14="rs-pure",D14="rs-sys"),OR(G14="rs-pure",G14="rs-sys")),1,0) -> 0 | AF14: =IF(C14=F14,1,0) -> 0 | AG14: =IF(B14=E14,1,0) -> 1 | AH14: =IF(SUM(AC14:AE14)=1,1,0) -> 1 | AI14: =IF(OR(AND($D14=AI$1,$G14=AI$2),AND($D14=AI$2,$G14=AI$1)),1,0) -> 0 | AJ14: =IF(OR(AND($D14=AJ$1,$G14=AJ$2),AND($D14=AJ$2,$G14=AJ$1)),1,0) -> 0 | AK14: =IF(OR(AND($D14=AK$1,$G14=AK$2),AND($D14=AK$2,$G14=AK$1)),1,0) -> 0 | AL14: =IF(OR(AND($D14=AL$1,$G14=AL$2),AND($D14=AL$2,$G14=AL$1)),1,0) -> 0 | AM14: =IF(OR(AND($D14=AM$1,$G14=AM$2),AND($D14=AM$2,$G14=AM$1)),1,0) -> 0 | AN14: =IF(OR(AND($D14=AN$1,$G14=AN$2),AND($D14=AN$2,$G14=AN$1)),1,0) -> 0 | AO14: =IF(OR(AND($D14=AO$1,$G14=AO$2),AND($D14=AO$2,$G14=AO$1)),1,0) -> 0 | AP14: =IF(OR(AND($D14=AP$1,$G14=AP$2),AND($D14=AP$2,$G14=AP$1)),1,0) -> 0 | ... AW14: =IF(OR(AND($D14=AW$1,$G14=AW$2),AND($D14=AW$2,$G14=AW$1)),1,0) -> 0 | AX14: =IF(OR(AND($C14=AX$1,$F14=AX$2),AND($C14=AX$2,$F14=AX$1)),1,0) -> 0 | AY14: =IF(OR(AND($C14=AY$1,$F14=AY$2),AND($C14=AY$2,$F14=AY$1)),1,0) -> 0 | AZ14: =IF(OR(AND($C14=AZ$1,$F14=AZ$2),AND($C14=AZ$2,$F14=AZ$1)),1,0) -> 1 | BA14: =IF(SUM(AI14:AQ14)=1,1,0) -> 0 | BB14: =IF(OR(C14="windows",F14="windows"),1,0) -> 1
... A668: 665 | B668: arm64 | C668: windows | D668: rs-sys | E668: arm64 | F668: windows | G668: rs-sys | H668: 1 | I668: 1 | J668: 1 | K668: 1 | L668: 1 | M668: 1 | N668: 1 | O668: 1 | P668: =IF(OR(AND($C668="linux",$D668="clang"),AND($F668="linux",$G668="clang")),1,0) -> 0 | Q668: =IF(OR(AND($C668="linux",$D668="gcc"),AND($F668="linux",$G668="gcc")),1,0) -> 0 | R668: =IF(OR(AND($C668="linux",$D668="go"),AND($F668="linux",$G668="go")),1,0) -> 0 | S668: =IF(OR(AND($C668="linux",$D668="tgo"),AND($F668="linux",$G668="tgo")),1,0) -> 0 | T668: =IF(OR(AND($C668="darwin",$D668="clang"),AND($F668="darwin",$G668="clang")),1,0) -> 0 | U668: =IF(OR(AND($C668="darwin",$D668="gcc"),AND($F668="darwin",$G668="gcc")),1,0) -> 0 | V668: =IF(OR(AND($C668="darwin",$D668="go"),AND($F668="darwin",$G668="go")),1,0) -> 0 | W668: =IF(OR(AND($C668="darwin",$D668="tgo"),AND($F668="darwin",$G668="tgo")),1,0) -> 0 | X668: =IF(OR(AND($C668="windows",$D668="clang"),AND($F668="windows",$G668="clang")),1,0) -> 0 | Y668: =IF(OR(AND($C668="windows",$D668="gcc"),AND($F668="windows",$G668="gcc")),1,0) -> 0 | Z668: =IF(OR(AND($C668="windows",$D668="msvc"),AND($F668="windows",$G668="msvc")),1,0) -> 0 | AA668: =IF(OR(AND($C668="windows",$D668="go"),AND($F668="windows",$G668="go")),1,0) -> 0 | AB668: =IF(AND(AND(C668="windows",D668="clang"),AND(F668="windows",G668="clang")),1,0) -> 0 | AC668: =IF(AND(OR(D668="clang",D668="gcc",D668="msvc"),OR(G668="gcc",G668="clang",G668="msvc")),1,0) -> 0 | AD668: =IF(AND(OR(D668="go",D668="tgo"),OR(G668="go",G668="tgo")),1,0) -> 0 | AE668: =IF(AND(OR(D668="rs-pure",D668="rs-sys"),OR(G668="rs-pure",G668="rs-sys")),1,0) -> 1 | AF668: =IF(C668=F668,1,0) -> 1 | AG668: =IF(B668=E668,1,0) -> 1 | AH668: =IF(SUM(AC668:AE668)=1,1,0) -> 1 | AI668: =IF(OR(AND($D668=AI$1,$G668=AI$2),AND($D668=AI$2,$G668=AI$1)),1,0) -> 0 | AJ668: =IF(OR(AND($D668=AJ$1,$G668=AJ$2),AND($D668=AJ$2,$G668=AJ$1)),1,0) -> 0 | AK668: =IF(OR(AND($D668=AK$1,$G668=AK$2),AND($D668=AK$2,$G668=AK$1)),1,0) -> 0 | AL668: =IF(OR(AND($D668=AL$1,$G668=AL$2),AND($D668=AL$2,$G668=AL$1)),1,0) -> 0 | AM668: =IF(OR(AND($D668=AM$1,$G668=AM$2),AND($D668=AM$2,$G668=AM$1)),1,0) -> 0 | AN668: =IF(OR(AND($D668=AN$1,$G668=AN$2),AND($D668=AN$2,$G668=AN$1)),1,0) -> 0 | AO668: =IF(OR(AND($D668=AO$1,$G668=AO$2),AND($D668=AO$2,$G668=AO$1)),1,0) -> 0 | AP668: =IF(OR(AND($D668=AP$1,$G668=AP$2),AND($D668=AP$2,$G668=AP$1)),1,0) -> 0 | ... AW668: =IF(OR(AND($D668=AW$1,$G668=AW$2),AND($D668=AW$2,$G668=AW$1)),1,0) -> 0 | AX668: =IF(OR(AND($C668=AX$1,$F668=AX$2),AND($C668=AX$2,$F668=AX$1)),1,0) -> 0 | AY668: =IF(OR(AND($C668=AY$1,$F668=AY$2),AND($C668=AY$2,$F668=AY$1)),1,0) -> 0 | AZ668: =IF(OR(AND($C668=AZ$1,$F668=AZ$2),AND($C668=AZ$2,$F668=AZ$1)),1,0) -> 0 | BA668: =IF(SUM(AI668:AQ668)=1,1,0) -> 0 | BB668: =IF(OR(C668="windows",F668="windows"),1,0) -> 1

Sheet Bullet in Report
A1: Clang (Windows) | B1: Clang (Linux) | C1: Gcc (Linux) | D1: Go (Linux) | E1: TinyGo (Linux) | F1: Clang (Darwin) | G1: Gcc (Darwin) | H1: Go (Darwin) | I1: TinyGo (Darwin) | J1: Clang (Windows) | K1: Gcc (Windows) | L1: MSVC (Windows) | M1: Go (Windows)
A2: Cosine | B2: =AVERAGEIFS(whole_data!$H$3:$H$668,whole_data!$X$3:$X$668, 1, whole_data!P$3:P$668,1) -> 0.027900949 | C2: =AVERAGEIFS(whole_data!$H$3:$H$668,whole_data!$X$3:$X$668, 1, whole_data!Q$3:Q$668,1) -> 0.03183859 | D2: =AVERAGEIFS(whole_data!$H$3:$H$668,whole_data!$X$3:$X$668, 1, whole_data!R$3:R$668,1) -> 0.74131269 | E2: =AVERAGEIFS(whole_data!$H$3:$H$668,whole_data!$X$3:$X$668, 1, whole_data!S$3:S$668,1) -> 0.33756652 | F2: =AVERAGEIFS(whole_data!$H$3:$H$668,whole_data!$X$3:$X$668, 1, whole_data!T$3:T$668,1) -> 0.026136203 | G2: =AVERAGEIFS(whole_data!$H$3:$H$668,whole_data!$X$3:$X$668, 1, whole_data!U$3:U$668,1) -> 0.027782281 | H2: =AVERAGEIFS(whole_data!$H$3:$H$668,whole_data!$X$3:$X$668, 1, whole_data!V$3:V$668,1) -> 0.74111737 | I2: =AVERAGEIFS(whole_data!$H$3:$H$668,whole_data!$X$3:$X$668, 1, whole_data!W$3:W$668,1) -> 0.28348808 | ... M2: =AVERAGEIFS(whole_data!$H$3:$H$668,whole_data!$X$3:$X$668, 1, whole_data!AA$3:AA$668,1) -> 0.70943281
A3: Dice | B3: =AVERAGEIFS(whole_data!$I$3:$I$668,whole_data!$X$3:$X$668, 1, whole_data!P$3:P$668,1) -> 0.028027077 | C3: =AVERAGEIFS(whole_data!$I$3:$I$668,whole_data!$X$3:$X$668, 1, whole_data!Q$3:Q$668,1) -> 0.03152528 | D3: =AVERAGEIFS(whole_data!$I$3:$I$668,whole_data!$X$3:$X$668, 1, whole_data!R$3:R$668,1) -> 0.71763887 | E3: =AVERAGEIFS(whole_data!$I$3:$I$668,whole_data!$X$3:$X$668, 1, whole_data!S$3:S$668,1) -> 0.32607676 | F3: =AVERAGEIFS(whole_data!$I$3:$I$668,whole_data!$X$3:$X$668, 1, whole_data!T$3:T$668,1) -> 0.025900058 | G3: =AVERAGEIFS(whole_data!$I$3:$I$668,whole_data!$X$3:$X$668, 1, whole_data!U$3:U$668,1) -> 0.027118354 | H3: =AVERAGEIFS(whole_data!$I$3:$I$668,whole_data!$X$3:$X$668, 1, whole_data!V$3:V$668,1) -> 0.72365834 | I3: =AVERAGEIFS(whole_data!$I$3:$I$668,whole_data!$X$3:$X$668, 1, whole_data!W$3:W$668,1) -> 0.27258933 | ... M3: =AVERAGEIFS(whole_data!$I$3:$I$668,whole_data!$X$3:$X$668, 1, whole_data!AA$3:AA$668,1) -> 0.67368242
A4: Euclidean | B4: =AVERAGEIFS(whole_data!$J$3:$J$668,whole_data!$X$3:$X$668, 1, whole_data!P$3:P$668,1) -> 0.02419577 | C4: =AVERAGEIFS(whole_data!$J$3:$J$668,whole_data!$X$3:$X$668, 1, whole_data!Q$3:Q$668,1) -> 0.02729676 | D4: =AVERAGEIFS(whole_data!$J$3:$J$668,whole_data!$X$3:$X$668, 1, whole_data!R$3:R$668,1) -> 0.55410183 | E4: =AVERAGEIFS(whole_data!$J$3:$J$668,whole_data!$X$3:$X$668, 1, whole_data!S$3:S$668,1) -> 0.28144134 | F4: =AVERAGEIFS(whole_data!$J$3:$J$668,whole_data!$X$3:$X$668, 1, whole_data!T$3:T$668,1) -> 0.02270128 | G4: =AVERAGEIFS(whole_data!$J$3:$J$668,whole_data!$X$3:$X$668, 1, whole_data!U$3:U$668,1) -> 0.023638256 | H4: =AVERAGEIFS(whole_data!$J$3:$J$668,whole_data!$X$3:$X$668, 1, whole_data!V$3:V$668,1) -> 0.55507835 | I4: =AVERAGEIFS(whole_data!$J$3:$J$668,whole_data!$X$3:$X$668, 1, whole_data!W$3:W$668,1) -> 0.2394648 | ... M4: =AVERAGEIFS(whole_data!$J$3:$J$668,whole_data!$X$3:$X$668, 1, whole_data!AA$3:AA$668,1) -> 0.53660155
A5: Jaccard | B5: =AVERAGEIFS(whole_data!$K$3:$K$668,whole_data!$X$3:$X$668, 1, whole_data!P$3:P$668,1) -> 0.026663826 | C5: =AVERAGEIFS(whole_data!$K$3:$K$668,whole_data!$X$3:$X$668, 1, whole_data!Q$3:Q$668,1) -> 0.029575911 | D5: =AVERAGEIFS(whole_data!$K$3:$K$668,whole_data!$X$3:$X$668, 1, whole_data!R$3:R$668,1) -> 0.61186141 | E5: =AVERAGEIFS(whole_data!$K$3:$K$668,whole_data!$X$3:$X$668, 1, whole_data!S$3:S$668,1) -> 0.28558518 | F5: =AVERAGEIFS(whole_data!$K$3:$K$668,whole_data!$X$3:$X$668, 1, whole_data!T$3:T$668,1) -> 0.02469405 | G5: =AVERAGEIFS(whole_data!$K$3:$K$668,whole_data!$X$3:$X$668, 1, whole_data!U$3:U$668,1) -> 0.025360019 | H5: =AVERAGEIFS(whole_data!$K$3:$K$668,whole_data!$X$3:$X$668, 1, whole_data!V$3:V$668,1) -> 0.61806734 | I5: =AVERAGEIFS(whole_data!$K$3:$K$668,whole_data!$X$3:$X$668, 1, whole_data!W$3:W$668,1) -> 0.24135752 | ... M5: =AVERAGEIFS(whole_data!$K$3:$K$668,whole_data!$X$3:$X$668, 1, whole_data!AA$3:AA$668,1) -> 0.58082073
A6: LCS | B6: =AVERAGEIFS(whole_data!$L$3:$L$668,whole_data!$X$3:$X$668, 1, whole_data!P$3:P$668,1) -> 0.021295039 | C6: =AVERAGEIFS(whole_data!$L$3:$L$668,whole_data!$X$3:$X$668, 1, whole_data!Q$3:Q$668,1) -> 0.021256036 | D6: =AVERAGEIFS(whole_data!$L$3:$L$668,whole_data!$X$3:$X$668, 1, whole_data!R$3:R$668,1) -> 0.40784673 | E6: =AVERAGEIFS(whole_data!$L$3:$L$668,whole_data!$X$3:$X$668, 1, whole_data!S$3:S$668,1) -> 0.22507545 | F6: =AVERAGEIFS(whole_data!$L$3:$L$668,whole_data!$X$3:$X$668, 1, whole_data!T$3:T$668,1) -> 0.01982895 | G6: =AVERAGEIFS(whole_data!$L$3:$L$668,whole_data!$X$3:$X$668, 1, whole_data!U$3:U$668,1) -> 0.017955659 | H6: =AVERAGEIFS(whole_data!$L$3:$L$668,whole_data!$X$3:$X$668, 1, whole_data!V$3:V$668,1) -> 0.41188602 | I6: =AVERAGEIFS(whole_data!$L$3:$L$668,whole_data!$X$3:$X$668, 1, whole_data!W$3:W$668,1) -> 0.19351418 | ... M6: =AVERAGEIFS(whole_data!$L$3:$L$668,whole_data!$X$3:$X$668, 1, whole_data!AA$3:AA$668,1) -> 0.38446913
A7: Levenshtein | B7: =AVERAGEIFS(whole_data!$M$3:$M$668,whole_data!$X$3:$X$668, 1, whole_data!P$3:P$668,1) -> 0.017966109 | C7: =AVERAGEIFS(whole_data!$M$3:$M$668,whole_data!$X$3:$X$668, 1, whole_data!Q$3:Q$668,1) -> 0.016954389 | D7: =AVERAGEIFS(whole_data!$M$3:$M$668,whole_data!$X$3:$X$668, 1, whole_data!R$3:R$668,1) -> 0.30012132 | E7: =AVERAGEIFS(whole_data!$M$3:$M$668,whole_data!$X$3:$X$668, 1, whole_data!S$3:S$668,1) -> 0.17425814 | F7: =AVERAGEIFS(whole_data!$M$3:$M$668,whole_data!$X$3:$X$668, 1, whole_data!T$3:T$668,1) -> 0.016517812 | G7: =AVERAGEIFS(whole_data!$M$3:$M$668,whole_data!$X$3:$X$668, 1, whole_data!U$3:U$668,1) -> 0.013975141 | H7: =AVERAGEIFS(whole_data!$M$3:$M$668,whole_data!$X$3:$X$668, 1, whole_data!V$3:V$668,1) -> 0.30074124 | I7: =AVERAGEIFS(whole_data!$M$3:$M$668,whole_data!$X$3:$X$668, 1, whole_data!W$3:W$668,1) -> 0.15153027 | ... M7: =AVERAGEIFS(whole_data!$M$3:$M$668,whole_data!$X$3:$X$668, 1, whole_data!AA$3:AA$668,1) -> 0.28045882
A8: Simpson | B8: =AVERAGEIFS(whole_data!$N$3:$N$668,whole_data!$X$3:$X$668, 1, whole_data!P$3:P$668,1) -> 0.029728792 | C8: =AVERAGEIFS(whole_data!$N$3:$N$668,whole_data!$X$3:$X$668, 1, whole_data!Q$3:Q$668,1) -> 0.034037312 | D8: =AVERAGEIFS(whole_data!$N$3:$N$668,whole_data!$X$3:$X$668, 1, whole_data!R$3:R$668,1) -> 0.90000728 | E8: =AVERAGEIFS(whole_data!$N$3:$N$668,whole_data!$X$3:$X$668, 1, whole_data!S$3:S$668,1) -> 0.41232542 | F8: =AVERAGEIFS(whole_data!$N$3:$N$668,whole_data!$X$3:$X$668, 1, whole_data!T$3:T$668,1) -> 0.027359105 | G8: =AVERAGEIFS(whole_data!$N$3:$N$668,whole_data!$X$3:$X$668, 1, whole_data!U$3:U$668,1) -> 0.02929794 | H8: =AVERAGEIFS(whole_data!$N$3:$N$668,whole_data!$X$3:$X$668, 1, whole_data!V$3:V$668,1) -> 0.90159885 | I8: =AVERAGEIFS(whole_data!$N$3:$N$668,whole_data!$X$3:$X$668, 1, whole_data!W$3:W$668,1) -> 0.33714173 | ... M8: =AVERAGEIFS(whole_data!$N$3:$N$668,whole_data!$X$3:$X$668, 1, whole_data!AA$3:AA$668,1) -> 0.82159131
A9: Weighted-Jaccard | B9: =AVERAGEIFS(whole_data!$O$3:$O$668,whole_data!$X$3:$X$668, 1, whole_data!P$3:P$668,1) -> 0.021458352 | C9: =AVERAGEIFS(whole_data!$O$3:$O$668,whole_data!$X$3:$X$668, 1, whole_data!Q$3:Q$668,1) -> 0.023123201 | D9: =AVERAGEIFS(whole_data!$O$3:$O$668,whole_data!$X$3:$X$668, 1, whole_data!R$3:R$668,1) -> 0.42643455 | E9: =AVERAGEIFS(whole_data!$O$3:$O$668,whole_data!$X$3:$X$668, 1, whole_data!S$3:S$668,1) -> 0.22514343 | F9: =AVERAGEIFS(whole_data!$O$3:$O$668,whole_data!$X$3:$X$668, 1, whole_data!T$3:T$668,1) -> 0.020368978 | G9: =AVERAGEIFS(whole_data!$O$3:$O$668,whole_data!$X$3:$X$668, 1, whole_data!U$3:U$668,1) -> 0.019934639 | H9: =AVERAGEIFS(whole_data!$O$3:$O$668,whole_data!$X$3:$X$668, 1, whole_data!V$3:V$668,1) -> 0.42691329 | I9: =AVERAGEIFS(whole_data!$O$3:$O$668,whole_data!$X$3:$X$668, 1, whole_data!W$3:W$668,1) -> 0.19489139 | ... M9: =AVERAGEIFS(whole_data!$O$3:$O$668,whole_data!$X$3:$X$668, 1, whole_data!AA$3:AA$668,1) -> 0.41518391
A14: MSVC (Windows) | B14: Clang (Linux) | C14: Gcc (Linux) | D14: Go (Linux) | E14: TinyGo (Linux) | F14: Clang (Darwin) | G14: Gcc (Darwin) | H14: Go (Darwin) | I14: TinyGo (Darwin) | J14: Clang (Windows) | K14: Gcc (Windows) | L14: MSVC (Windows) | M14: Go (Windows)
A15: Cosine | B15: =AVERAGEIFS(whole_data!$H$3:$H$668,whole_data!$Z$3:$Z$668, 1, whole_data!P$3:P$668,1) -> 0.46159033 | C15: =AVERAGEIFS(whole_data!$H$3:$H$668,whole_data!$Z$3:$Z$668, 1, whole_data!Q$3:Q$668,1) -> 0.52400877 | D15: =AVERAGEIFS(whole_data!$H$3:$H$668,whole_data!$Z$3:$Z$668, 1, whole_data!R$3:R$668,1) -> 0.047824785 | E15: =AVERAGEIFS(whole_data!$H$3:$H$668,whole_data!$Z$3:$Z$668, 1, whole_data!S$3:S$668,1) -> 0.13448818 | F15: =AVERAGEIFS(whole_data!$H$3:$H$668,whole_data!$Z$3:$Z$668, 1, whole_data!T$3:T$668,1) -> 0.43801263 | G15: =AVERAGEIFS(whole_data!$H$3:$H$668,whole_data!$Z$3:$Z$668, 1, whole_data!U$3:U$668,1) -> 0.46644401 | H15: =AVERAGEIFS(whole_data!$H$3:$H$668,whole_data!$Z$3:$Z$668, 1, whole_data!V$3:V$668,1) -> 0.047685387 | I15: =AVERAGEIFS(whole_data!$H$3:$H$668,whole_data!$Z$3:$Z$668, 1, whole_data!W$3:W$668,1) -> 0.16498324 | ... M15: =AVERAGEIFS(whole_data!$H$3:$H$668,whole_data!$Z$3:$Z$668, 1, whole_data!AA$3:AA$668,1) -> 0.06097232
A16: Dice | B16: =AVERAGEIFS(whole_data!$I$3:$I$668,whole_data!$Z$3:$Z$668, 1, whole_data!P$3:P$668,1) -> 0.4541065 | C16: =AVERAGEIFS(whole_data!$I$3:$I$668,whole_data!$Z$3:$Z$668, 1, whole_data!Q$3:Q$668,1) -> 0.52088286 | D16: =AVERAGEIFS(whole_data!$I$3:$I$668,whole_data!$Z$3:$Z$668, 1, whole_data!R$3:R$668,1) -> 0.0455908 | E16: =AVERAGEIFS(whole_data!$I$3:$I$668,whole_data!$Z$3:$Z$668, 1, whole_data!S$3:S$668,1) -> 0.12826085 | F16: =AVERAGEIFS(whole_data!$I$3:$I$668,whole_data!$Z$3:$Z$668, 1, whole_data!T$3:T$668,1) -> 0.41454149 | G16: =AVERAGEIFS(whole_data!$I$3:$I$668,whole_data!$Z$3:$Z$668, 1, whole_data!U$3:U$668,1) -> 0.44241516 | H16: =AVERAGEIFS(whole_data!$I$3:$I$668,whole_data!$Z$3:$Z$668, 1, whole_data!V$3:V$668,1) -> 0.045228301 | I16: =AVERAGEIFS(whole_data!$I$3:$I$668,whole_data!$Z$3:$Z$668, 1, whole_data!W$3:W$668,1) -> 0.15563546 | ... M16: =AVERAGEIFS(whole_data!$I$3:$I$668,whole_data!$Z$3:$Z$668, 1, whole_data!AA$3:AA$668,1) -> 0.057779506
A17: Euclidean | B17: =AVERAGEIFS(whole_data!$J$3:$J$668,whole_data!$Z$3:$Z$668, 1, whole_data!P$3:P$668,1) -> 0.3733651 | C17: =AVERAGEIFS(whole_data!$J$3:$J$668,whole_data!$Z$3:$Z$668, 1, whole_data!Q$3:Q$668,1) -> 0.43167873 | D17: =AVERAGEIFS(whole_data!$J$3:$J$668,whole_data!$Z$3:$Z$668, 1, whole_data!R$3:R$668,1) -> 0.040967046 | E17: =AVERAGEIFS(whole_data!$J$3:$J$668,whole_data!$Z$3:$Z$668, 1, whole_data!S$3:S$668,1) -> 0.11242179 | F17: =AVERAGEIFS(whole_data!$J$3:$J$668,whole_data!$Z$3:$Z$668, 1, whole_data!T$3:T$668,1) -> 0.3515011 | G17: =AVERAGEIFS(whole_data!$J$3:$J$668,whole_data!$Z$3:$Z$668, 1, whole_data!U$3:U$668,1) -> 0.38242476 | H17: =AVERAGEIFS(whole_data!$J$3:$J$668,whole_data!$Z$3:$Z$668, 1, whole_data!V$3:V$668,1) -> 0.040425535 | I17: =AVERAGEIFS(whole_data!$J$3:$J$668,whole_data!$Z$3:$Z$668, 1, whole_data!W$3:W$668,1) -> 0.13705903 | ... M17: =AVERAGEIFS(whole_data!$J$3:$J$668,whole_data!$Z$3:$Z$668, 1, whole_data!AA$3:AA$668,1) -> 0.051938304
A18: Jaccard | B18: =AVERAGEIFS(whole_data!$K$3:$K$668,whole_data!$Z$3:$Z$668, 1, whole_data!P$3:P$668,1) -> 0.40722743 | C18: =AVERAGEIFS(whole_data!$K$3:$K$668,whole_data!$Z$3:$Z$668, 1, whole_data!Q$3:Q$668,1) -> 0.46684721 | D18: =AVERAGEIFS(whole_data!$K$3:$K$668,whole_data!$Z$3:$Z$668, 1, whole_data!R$3:R$668,1) -> 0.041199828 | E18: =AVERAGEIFS(whole_data!$K$3:$K$668,whole_data!$Z$3:$Z$668, 1, whole_data!S$3:S$668,1) -> 0.11422801 | F18: =AVERAGEIFS(whole_data!$K$3:$K$668,whole_data!$Z$3:$Z$668, 1, whole_data!T$3:T$668,1) -> 0.36907709 | G18: =AVERAGEIFS(whole_data!$K$3:$K$668,whole_data!$Z$3:$Z$668, 1, whole_data!U$3:U$668,1) -> 0.39220398 | H18: =AVERAGEIFS(whole_data!$K$3:$K$668,whole_data!$Z$3:$Z$668, 1, whole_data!V$3:V$668,1) -> 0.040592618 | I18: =AVERAGEIFS(whole_data!$K$3:$K$668,whole_data!$Z$3:$Z$668, 1, whole_data!W$3:W$668,1) -> 0.13833029 | ... M18: =AVERAGEIFS(whole_data!$K$3:$K$668,whole_data!$Z$3:$Z$668, 1, whole_data!AA$3:AA$668,1) -> 0.051989817
A19: LCS | B19: =AVERAGEIFS(whole_data!$L$3:$L$668,whole_data!$Z$3:$Z$668, 1, whole_data!P$3:P$668,1) -> 0.30559111 | C19: =AVERAGEIFS(whole_data!$L$3:$L$668,whole_data!$Z$3:$Z$668, 1, whole_data!Q$3:Q$668,1) -> 0.34726653 | D19: =AVERAGEIFS(whole_data!$L$3:$L$668,whole_data!$Z$3:$Z$668, 1, whole_data!R$3:R$668,1) -> 0.032172994 | E19: =AVERAGEIFS(whole_data!$L$3:$L$668,whole_data!$Z$3:$Z$668, 1, whole_data!S$3:S$668,1) -> 0.088137905 | F19: =AVERAGEIFS(whole_data!$L$3:$L$668,whole_data!$Z$3:$Z$668, 1, whole_data!T$3:T$668,1) -> 0.27997805 | G19: =AVERAGEIFS(whole_data!$L$3:$L$668,whole_data!$Z$3:$Z$668, 1, whole_data!U$3:U$668,1) -> 0.29685641 | H19: =AVERAGEIFS(whole_data!$L$3:$L$668,whole_data!$Z$3:$Z$668, 1, whole_data!V$3:V$668,1) -> 0.031650786 | I19: =AVERAGEIFS(whole_data!$L$3:$L$668,whole_data!$Z$3:$Z$668, 1, whole_data!W$3:W$668,1) -> 0.10728054 | ... M19: =AVERAGEIFS(whole_data!$L$3:$L$668,whole_data!$Z$3:$Z$668, 1, whole_data!AA$3:AA$668,1) -> 0.040776209
A20: Levenshtein | B20: =AVERAGEIFS(whole_data!$M$3:$M$668,whole_data!$Z$3:$Z$668, 1, whole_data!P$3:P$668,1) -> 0.23691162 | C20: =AVERAGEIFS(whole_data!$M$3:$M$668,whole_data!$Z$3:$Z$668, 1, whole_data!Q$3:Q$668,1) -> 0.26852987 | D20: =AVERAGEIFS(whole_data!$M$3:$M$668,whole_data!$Z$3:$Z$668, 1, whole_data!R$3:R$668,1) -> 0.025759218 | E20: =AVERAGEIFS(whole_data!$M$3:$M$668,whole_data!$Z$3:$Z$668, 1, whole_data!S$3:S$668,1) -> 0.069417997 | F20: =AVERAGEIFS(whole_data!$M$3:$M$668,whole_data!$Z$3:$Z$668, 1, whole_data!T$3:T$668,1) -> 0.21566717 | G20: =AVERAGEIFS(whole_data!$M$3:$M$668,whole_data!$Z$3:$Z$668, 1, whole_data!U$3:U$668,1) -> 0.22331105 | H20: =AVERAGEIFS(whole_data!$M$3:$M$668,whole_data!$Z$3:$Z$668, 1, whole_data!V$3:V$668,1) -> 0.025007302 | I20: =AVERAGEIFS(whole_data!$M$3:$M$668,whole_data!$Z$3:$Z$668, 1, whole_data!W$3:W$668,1) -> 0.084322733 | ... M20: =AVERAGEIFS(whole_data!$M$3:$M$668,whole_data!$Z$3:$Z$668, 1, whole_data!AA$3:AA$668,1) -> 0.032477281
A21: Simpson | B21: =AVERAGEIFS(whole_data!$N$3:$N$668,whole_data!$Z$3:$Z$668, 1, whole_data!P$3:P$668,1) -> 0.5228473 | C21: =AVERAGEIFS(whole_data!$N$3:$N$668,whole_data!$Z$3:$Z$668, 1, whole_data!Q$3:Q$668,1) -> 0.59862227 | D21: =AVERAGEIFS(whole_data!$N$3:$N$668,whole_data!$Z$3:$Z$668, 1, whole_data!R$3:R$668,1) -> 0.051913948 | E21: =AVERAGEIFS(whole_data!$N$3:$N$668,whole_data!$Z$3:$Z$668, 1, whole_data!S$3:S$668,1) -> 0.14856176 | F21: =AVERAGEIFS(whole_data!$N$3:$N$668,whole_data!$Z$3:$Z$668, 1, whole_data!T$3:T$668,1) -> 0.48117107 | G21: =AVERAGEIFS(whole_data!$N$3:$N$668,whole_data!$Z$3:$Z$668, 1, whole_data!U$3:U$668,1) -> 0.5152698 | H21: =AVERAGEIFS(whole_data!$N$3:$N$668,whole_data!$Z$3:$Z$668, 1, whole_data!V$3:V$668,1) -> 0.052002604 | I21: =AVERAGEIFS(whole_data!$N$3:$N$668,whole_data!$Z$3:$Z$668, 1, whole_data!W$3:W$668,1) -> 0.18099189 | ... M21: =AVERAGEIFS(whole_data!$N$3:$N$668,whole_data!$Z$3:$Z$668, 1, whole_data!AA$3:AA$668,1) -> 0.066327739
A22: Weighted-Jaccard | B22: =AVERAGEIFS(whole_data!$O$3:$O$668,whole_data!$Z$3:$Z$668, 1, whole_data!P$3:P$668,1) -> 0.30406118 | C22: =AVERAGEIFS(whole_data!$O$3:$O$668,whole_data!$Z$3:$Z$668, 1, whole_data!Q$3:Q$668,1) -> 0.34632334 | D22: =AVERAGEIFS(whole_data!$O$3:$O$668,whole_data!$Z$3:$Z$668, 1, whole_data!R$3:R$668,1) -> 0.033508926 | E22: =AVERAGEIFS(whole_data!$O$3:$O$668,whole_data!$Z$3:$Z$668, 1, whole_data!S$3:S$668,1) -> 0.090311889 | F22: =AVERAGEIFS(whole_data!$O$3:$O$668,whole_data!$Z$3:$Z$668, 1, whole_data!T$3:T$668,1) -> 0.28608021 | G22: =AVERAGEIFS(whole_data!$O$3:$O$668,whole_data!$Z$3:$Z$668, 1, whole_data!U$3:U$668,1) -> 0.30688184 | H22: =AVERAGEIFS(whole_data!$O$3:$O$668,whole_data!$Z$3:$Z$668, 1, whole_data!V$3:V$668,1) -> 0.032562911 | I22: =AVERAGEIFS(whole_data!$O$3:$O$668,whole_data!$Z$3:$Z$668, 1, whole_data!W$3:W$668,1) -> 0.10984332 | ... M22: =AVERAGEIFS(whole_data!$O$3:$O$668,whole_data!$Z$3:$Z$668, 1, whole_data!AA$3:AA$668,1) -> 0.042303695

Sheet Windows
B1: left | E1: right
A2: 11 | B2: amd64 | C2: darwin | D2: clang | E2: amd64 | F2: windows | G2: clang
A3: 12 | B3: amd64 | C3: darwin | D3: clang | E3: amd64 | F3: windows | G3: gcc
A4: 13 | B4: amd64 | C4: darwin | D4: clang | E4: amd64 | F4: windows | G4: go
A5: 14 | B5: amd64 | C5: darwin | D5: clang | E5: amd64 | F5: windows | G5: msvc
A6: 15 | B6: amd64 | C6: darwin | D6: clang | E6: amd64 | F6: windows | G6: rs-pure
A7: 16 | B7: amd64 | C7: darwin | D7: clang | E7: amd64 | F7: windows | G7: rs-sys
A8: 29 | B8: amd64 | C8: darwin | D8: clang | E8: arm64 | F8: windows | G8: clang
A9: 30 | B9: amd64 | C9: darwin | D9: clang | E9: arm64 | F9: windows | G9: gcc
A10: 31 | B10: amd64 | C10: darwin | D10: clang | E10: arm64 | F10: windows | G10: go
A11: 32 | B11: amd64 | C11: darwin | D11: clang | E11: arm64 | F11: windows | G11: msvc
A12: 33 | B12: amd64 | C12: darwin | D12: clang | E12: arm64 | F12: windows | G12: rs-pure
A13: 34 | B13: amd64 | C13: darwin | D13: clang | E13: arm64 | F13: windows | G13: rs-sys
... A367: 665 | B367: arm64 | C367: windows | D367: rs-sys | E367: arm64 | F367: windows | G367: rs-sys

Sheet Rust
A1: rs-sys | T1: rs-sys | U1: rs-sys | V1: rs-pure | W1: rs-sys | X1: rs-pure | Y1: rs-sys | Z1: rs-sys | AA1: rs-pure | AB1: rs-pure
A2: rs-pure | B2: left | E2: right | H2: cosine | I2: dice | J2: euclidean | K2: jaccard | L2: lcs | M2: levenshtein | N2: simpson | O2: weighted-jaccard | T2: rs-pure | U2: clang | V2: clang | W2: gcc | X2: gcc | Y2: go | Z2: tgo | AA2: go | AB2: tgo
A3: 102 | B3: amd64 | C3: darwin | D3: rs-pure | E3: amd64 | F3: darwin | G3: rs-sys | H3: 0.98468231 | I3: 0.9832346 | J3: 0.98035128 | K3: 0.98086802 | L3: 0.97691202 | M3: 0.97382593 | N3: 0.98710812 | O3: 0.97680861 | R3: 4 | S3: 最大値 | T3: =QUARTILE($H$3:$O$38,$R3) -> 0.9985012 | U3: =QUARTILE($H$42:$O$77,$R3) -> 0.78816388 | V3: =QUARTILE($H$81:$O$116,$R3) -> 0.77847722 | W3: =QUARTILE($H$120:$O$155,$R3) -> 0.033687405 | X3: =QUARTILE($H$159:$O$194,$R3) -> 0.033273381 | Y3: =QUARTILE($H$237:$O$272,$R3) -> 0.78057663 | Z3: =QUARTILE($H$276:$O$299,$R3) -> 0.36813354 | AA3: =QUARTILE($H$303:$O$338,$R3) -> 0.77096448 | AB3: =QUARTILE($H$342:$O$365,$R3) -> 0.36360911
A4: 108 | B4: amd64 | C4: darwin | D4: rs-pure | E4: amd64 | F4: linux | G4: rs-sys | H4: 0.81498956 | I4: 0.84021541 | J4: 0.69089306 | K4: 0.7547466 | L4: 0.67715422 | M4: 0.57419278 | N4: 0.95366488 | O4: 0.60898143 | R4: 3 | S4: 第４四分位数 | T4: =QUARTILE($H$3:$O$38,$R4) -> 0.91198241 | U4: =QUARTILE($H$42:$O$77,$R4) -> 0.10173167 | V4: =QUARTILE($H$81:$O$116,$R4) -> 0.099390054 | W4: =QUARTILE($H$120:$O$155,$R4) -> 0.020443882 | X4: =QUARTILE($H$159:$O$194,$R4) -> 0.020120975 | Y4: =QUARTILE($H$237:$O$272,$R4) -> 0.54310734 | Z4: =QUARTILE($H$276:$O$299,$R4) -> 0.18963623 | AA4: =QUARTILE($H$303:$O$338,$R4) -> 0.53758404 | AB4: =QUARTILE($H$342:$O$365,$R4) -> 0.18716842
A5: 115 | B5: amd64 | C5: darwin | D5: rs-pure | E5: amd64 | F5: windows | G5: rs-sys | H5: 0.14061778 | I5: 0.13839623 | J5: 0.11767128 | K5: 0.12740363 | L5: 0.098673766 | M5: 0.082145162 | N5: 0.15351745 | O5: 0.097700387 | R5: 2 | S5: 中央値 | T5: =QUARTILE($H$3:$O$38,$R5) -> 0.62552086 | U5: =QUARTILE($H$42:$O$77,$R5) -> 0.017232622 | V5: =QUARTILE($H$81:$O$116,$R5) -> 0.016925185 | W5: =QUARTILE($H$120:$O$155,$R5) -> 0.01526828 | X5: =QUARTILE($H$159:$O$194,$R5) -> 0.015100131 | Y5: =QUARTILE($H$237:$O$272,$R5) -> 0.35371594 | Z5: =QUARTILE($H$276:$O$299,$R5) -> 0.13711743 | AA5: =QUARTILE($H$303:$O$338,$R5) -> 0.3498405 | AB5: =QUARTILE($H$342:$O$365,$R5) -> 0.13559256
A6: 120 | B6: amd64 | C6: darwin | D6: rs-pure | E6: arm64 | F6: darwin | G6: rs-sys | H6: 0.92732453 | I6: 0.9175212 | J6: 0.84929088 | K6: 0.88155512 | L6: 0.77543156 | M6: 0.68624977 | N6: 0.96542631 | O6: 0.80275219 | R6: 1 | S6: 第２四分位数 | T6: =QUARTILE($H$3:$O$38,$R6) -> 0.12944275 | U6: =QUARTILE($H$42:$O$77,$R6) -> 0.0097137225 | V6: =QUARTILE($H$81:$O$116,$R6) -> 0.0095549396 | W6: =QUARTILE($H$120:$O$155,$R6) -> 0.0038199244 | X6: =QUARTILE($H$159:$O$194,$R6) -> 0.0037278235 | Y6: =QUARTILE($H$237:$O$272,$R6) -> 0.10185622 | Z6: =QUARTILE($H$276:$O$299,$R6) -> 0.045549068 | AA6: =QUARTILE($H$303:$O$338,$R6) -> 0.099673551 | AB6: =QUARTILE($H$342:$O$365,$R6) -> 0.044473946
A7: 126 | B7: amd64 | C7: darwin | D7: rs-pure | E7: arm64 | F7: linux | G7: rs-sys | H7: 0.92097703 | I7: 0.91013614 | J7: 0.82066774 | K7: 0.86042812 | L7: 0.74001456 | M7: 0.63658055 | N7: 0.97597422 | O7: 0.76124668 | R7: 0 | S7: 最小値 | T7: =QUARTILE($H$3:$O$38,$R7) -> 0.068232141 | U7: =QUARTILE($H$42:$O$77,$R7) -> 0.0013773886 | V7: =QUARTILE($H$81:$O$116,$R7) -> 0.001341792 | W7: =QUARTILE($H$120:$O$155,$R7) -> 0.0013901797 | X7: =QUARTILE($H$159:$O$194,$R7) -> 0.0013504066 | Y7: =QUARTILE($H$237:$O$272,$R7) -> 0.031387159 | Z7: =QUARTILE($H$276:$O$299,$R7) -> 0.012829965 | AA7: =QUARTILE($H$303:$O$338,$R7) -> 0.030587457 | AB7: =QUARTILE($H$342:$O$365,$R7) -> 0.01252189
A8: 133 | B8: amd64 | C8: darwin | D8: rs-pure | E8: arm64 | F8: windows | G8: rs-sys | H8: 0.15893296 | I8: 0.15660391 | J8: 0.13249206 | K8: 0.14319091 | L8: 0.10956095 | M8: 0.089341657 | N8: 0.17520534 | O8: 0.10892552
A9: 138 | B9: amd64 | C9: darwin | D9: rs-sys | E9: amd64 | F9: linux | G9: rs-pure | H9: 0.82075155 | I9: 0.84292157 | J9: 0.69620812 | K9: 0.75642165 | L9: 0.6828861 | M9: 0.57962911 | N9: 0.97080175 | O9: 0.61446117 | T9: rs-sys | U9: rs-sys | V9: rs-pure | W9: rs-sys | X9: rs-pure | Y9: rs-sys | Z9: rs-sys | AA9: rs-pure | AB9: rs-pure
A10: 145 | B10: amd64 | C10: darwin | D10: rs-sys | E10: amd64 | F10: windows | G10: rs-pure | H10: 0.13577119 | I10: 0.13381037 | J10: 0.11381221 | K10: 0.12344836 | L10: 0.095573406 | M10: 0.079689443 | N10: 0.14797734 | O10: 0.094808306 | T10: rs-pure | U10: clang | V10: clang | W10: gcc | X10: gcc | Y10: go | Z10: tgo | AA10: go | AB10: tgo
A11: 150 | B11: amd64 | C11: darwin | D11: rs-sys | E11: arm64 | F11: darwin | G11: rs-pure | H11: 0.94788859 | I11: 0.93858887 | J11: 0.86542219 | K11: 0.90028046 | L11: 0.78945492 | M11: 0.69812544 | N11: 0.99020481 | O11: 0.81640609 | T11: Rust (libbz2) vs Rust (Pure) | U11: Rust (libbz2) vs Clang | V11: Rust (Pure) vs Clang | W11: Rust (libbz2) vs Gcc | X11: Rust (Pure) vs Gcc | Y11: Rust (libbz2) vs Go | Z11: Rust (libbz2) vs TinyGo | AA11: Rust (Pure) vs Go | AB11: Rust (Pure) vs TinyGo
A12: 156 | B12: amd64 | C12: darwin | D12: rs-sys | E12: arm64 | F12: linux | G12: rs-pure | H12: 0.93841794 | I12: 0.92728276 | J12: 0.83274928 | K12: 0.87566829 | L12: 0.75093121 | M12: 0.64599865 | N12: 0.9961438 | O12: 0.77135344 | S12: 最大値−75% | T12: =T3-T4 -> 0.086518792 | U12: =U3-U4 -> 0.68643222 | V12: =V3-V4 -> 0.67908716 | W12: =W3-W4 -> 0.013243524 | X12: =X3-X4 -> 0.013152406 | Y12: =Y3-Y4 -> 0.23746929 | Z12: =Z3-Z4 -> 0.1784973 | AA12: =AA3-AA4 -> 0.23338044 | AB12: =AB3-AB4 -> 0.17644069
A13: 163 | B13: amd64 | C13: darwin | D13: rs-sys | E13: arm64 | F13: windows | G13: rs-pure | H13: 0.15368931 | I13: 0.15175623 | J13: 0.12830412 | K13: 0.13914055 | L13: 0.10620888 | M13: 0.086743032 | N13: 0.16911383 | O13: 0.105812 | S13: 75%−中央値 | T13: =T4-T5 -> 0.28646155 | U13: =U4-U5 -> 0.084499045 | V13: =V4-V5 -> 0.08246487 | W13: =W4-W5 -> 0.0051756016 | X13: =X4-X5 -> 0.0050208441 | Y13: =Y4-Y5 -> 0.1893914 | Z13: =Z4-Z5 -> 0.052518801 | AA13: =AA4-AA5 -> 0.18774354 | AB13: =AB4-AB5 -> 0.051575859
A14: 279 | B14: amd64 | C14: linux | D14: rs-pure | E14: amd64 | F14: linux | G14: rs-sys | H14: 0.98371536 | I14: 0.98228011 | J14: 0.97878057 | K14: 0.98025299 | L14: 0.97571876 | M14: 0.97245768 | N14: 0.98523767 | O14: 0.97562757 | S14: 中央値−25% | T14: =T5-T6 -> 0.49607811 | U14: =U5-U6 -> 0.0075188991 | V14: =V5-V6 -> 0.0073702453 | W14: =W5-W6 -> 0.011448356 | X14: =X5-X6 -> 0.011372308 | Y14: =Y5-Y6 -> 0.25185972 | Z14: =Z5-Z6 -> 0.091568365 | AA14: =AA5-AA6 -> 0.25016695 | AB14: =AB5-AB6 -> 0.091118617
A15: 286 | B15: amd64 | C15: linux | D15: rs-pure | E15: amd64 | F15: windows | G15: rs-sys | H15: 0.13664842 | I15: 0.12691145 | J15: 0.1152538 | K15: 0.11016807 | L15: 0.087912067 | M15: 0.070755677 | N15: 0.15234797 | O15: 0.088966451 | S15: 0.25 | T15: =T6 -> 0.12944275 | U15: =U6 -> 0.0097137225 | V15: =V6 -> 0.0095549396 | W15: =W6 -> 0.0038199244 | X15: =X6 -> 0.0037278235 | Y15: =Y6 -> 0.10185622 | Z15: =Z6 -> 0.045549068 | AA15: =AA6 -> 0.099673551 | AB15: =AB6 -> 0.044473946
